Workbook

Sheet Addendum
E2: Engagement: Microsoft 365 CSP incentive
A3: Product Name | B3: Product SKU Name | C3: Product ID | D3: SKU ID | E3: M365 CSP Core | F3: M365 CSP Global Strategic Product Accelerator – Tier 1 | G3: M365 CSP Global Strategic Product Accelerator – Tier 2 | H3: M365 CSP Global Calling and Conference PSTN Accelerator | I3: M365 CSP Growth Accelerator
A4: 10-year audit log retention | B4: 10-Year Audit Log Retention Add On | C4: CFQ7TTC0HL8Z | D4: 0001 | E4: x
A5: 10-year audit log retention | B5: 10-Year Audit Log Retention Add On - Extended Service Term | C5: CFQ7TTC0HL8Z | D5: 000B | E5: x
A6: 10-year audit log retention | B6: 10-Year Audit Log Retention Add On for EDU | C6: CFQ7TTC0HL8Z | D6: 0004 | E6: x
A7: 10-year audit log retention | B7: 10-Year Audit Log Retention Add On for EDU - Extended Service Term | C7: CFQ7TTC0HL8Z | D7: 000C | E7: x
A8: 10-year audit log retention | B8: 10-Year Audit Log Retention Add On for FLW | C8: CFQ7TTC0HL8Z | D8: 0005 | E8: x
A9: 10-year audit log retention | B9: 10-Year Audit Log Retention Add On for FLW - Extended Service Term | C9: CFQ7TTC0HL8Z | D9: 000D | E9: x
A10: Advanced Communications | B10: Advanced Communications | C10: CFQ7TTC0HDK0 | D10: 000B | E10: x
A11: Advanced Communications | B11: Advanced Communications | C11: CFQ7TTC0HDK0 | D11: 0001 | E11: x
A12: Advanced Communications | B12: Advanced Communications - Extended Service Term | C12: CFQ7TTC0HDK0 | D12: 000N | E12: x
A13: Advanced Communications | B13: Advanced Communications - Extended Service Term | C13: CFQ7TTC0HDK0 | D13: 000R | E13: x
A14: Advanced Communications | B14: Advanced Communications for faculty | C14: CFQ7TTC0HDK0 | D14: 000C | E14: x
A15: Advanced Communications | B15: Advanced Communications for faculty - Extended Service Term | C15: CFQ7TTC0HDK0 | D15: 000L | E15: x
... A19: Advanced Communications | B19: Advanced Communications for students - Extended Service Term | C19: CFQ7TTC0HDK0 | D19: 000M | E19: x
A20: Advanced Security Add-ons for Business Premium | B20: Microsoft Defender and Purview Suites for Microsoft 365 Business Premium - New | C20: CFQ7TTC10RSN | D20: 0003 | E20: x | F20: x | I20: x
A21: Advanced Security Add-ons for Business Premium | B21: Microsoft Defender and Purview Suites for Microsoft 365 Business Premium - New | C21: CFQ7TTC10RSN | D21: 0009 | E21: x | F21: x | I21: x
A22: Advanced Security Add-ons for Business Premium | B22: Microsoft Defender and Purview Suites for Microsoft 365 Business Premium - New - Extended Service Term | C22: CFQ7TTC10RSN | D22: 000P | E22: x | F22: x | I22: x
A23: Advanced Security Add-ons for Business Premium | B23: Microsoft Defender and Purview Suites for Microsoft 365 Business Premium - New - Extended Service Term | C23: CFQ7TTC10RSN | D23: 000L | E23: x | F23: x | I23: x
A24: Advanced Security Add-ons for Business Premium | B24: Microsoft Defender Suite for Microsoft 365 Business Premium - New | C24: CFQ7TTC10RSN | D24: 0001 | E24: x | F24: x | I24: x
A25: Advanced Security Add-ons for Business Premium | B25: Microsoft Defender Suite for Microsoft 365 Business Premium - New | C25: CFQ7TTC10RSN | D25: 0008 | E25: x | F25: x | I25: x
A26: Advanced Security Add-ons for Business Premium | B26: Microsoft Defender Suite for Microsoft 365 Business Premium - New - Extended Service Term | C26: CFQ7TTC10RSN | D26: 000M | E26: x | F26: x | I26: x
A27: Advanced Security Add-ons for Business Premium | B27: Microsoft Defender Suite for Microsoft 365 Business Premium - New - Extended Service Term | C27: CFQ7TTC10RSN | D27: 000K | E27: x | F27: x | I27: x
A28: Advanced Security Add-ons for Business Premium | B28: Microsoft Purview Suite for Microsoft 365 Business Premium - New | C28: CFQ7TTC10RSN | D28: 0002 | E28: x | F28: x | I28: x
A29: Advanced Security Add-ons for Business Premium | B29: Microsoft Purview Suite for Microsoft 365 Business Premium - New | C29: CFQ7TTC10RSN | D29: 0007 | E29: x | F29: x | I29: x
A30: Advanced Security Add-ons for Business Premium | B30: Microsoft Purview Suite for Microsoft 365 Business Premium - New - Extended Service Term | C30: CFQ7TTC10RSN | D30: 000N | E30: x | F30: x | I30: x
A31: Advanced Security Add-ons for Business Premium | B31: Microsoft Purview Suite for Microsoft 365 Business Premium - New - Extended Service Term | C31: CFQ7TTC10RSN | D31: 000J | E31: x | F31: x | I31: x
A32: Agent 365 | B32: Agent 365 | C32: CFQ7TTBZZR6G | D32: 0002 | E32: x | G32: x | I32: x
A33: Agent 365 | B33: Agent 365 - Extended Service Term | C33: CFQ7TTBZZR6G | D33: 0003 | E33: x | G33: x | I33: x
A34: Agent 365 | B34: Agent 365 (Education Faculty) | C34: CFQ7TTBZZR6G | D34: 0005 | E34: x | G34: x | I34: x
A35: Agent 365 | B35: Agent 365 (Education Faculty) | C35: CFQ7TTBZZR6G | D35: 0006 | E35: x | G35: x | I35: x
A36: Agent 365 | B36: Agent 365 (Education Faculty) - Extended Service Term | C36: CFQ7TTBZZR6G | D36: 0008 | E36: x | G36: x | I36: x
A37: Agent 365 | B37: Agent 365 (Education Student) | C37: CFQ7TTBZZR6G | D37: 0004 | E37: x | G37: x | I37: x
A38: Agent 365 | B38: Agent 365 (Education Student) | C38: CFQ7TTBZZR6G | D38: 0009 | E38: x | G38: x | I38: x
A39: Agent 365 | B39: Agent 365 (Education Student) - Extended Service Term | C39: CFQ7TTBZZR6G | D39: 0007 | E39: x | G39: x | I39: x
A40: Audio Conferencing (outbound, outside-US) | B40: Audio Conferencing (outbound, outside-US) | C40: CFQ7TTC0JL2W | D40: 0001 | E40: x
A41: Audio Conferencing (outbound, US) | B41: Audio Conferencing (outbound, US) | C41: CFQ7TTC0JL2S | D41: 0001 | E41: x
A42: Australia Calling Plan | B42: Australia Calling Plan | C42: CFQ7TTC0LHRW | D42: 0001 | E42: x
A43: Australia Calling Plan | B43: Australia Calling Plan - Extended Service Term | C43: CFQ7TTC0LHRW | D43: 0002 | E43: x
A44: Azure Active Directory Basic | B44: Azure Active Directory Basic | C44: CFQ7TTC0LH1X | D44: 000G | E44: x
...

Sheet Master Input Sheet
A1: Last Updated Date | B1: 46248
A2: Last Updated Time | B2: 0.80625
A3: Legend | B3: To be Filled
A7: ProductId | B7: SkuId | C7: SkuTitle | D7: TermDuration | E7: BillingPlan | F7: ERP Price | G7: UnitPrice/Catalogue Price
A8: CFQ7TTC0HL8Z | B8: 1 | C8: 10-Year Audit Log Retention Add On | D8: P1Y | E8: Monthly | F8: 2079 | G8: 1663.2
A9: CFQ7TTC0HL8Z | B9: 1 | C9: 10-Year Audit Log Retention Add On | D9: P1Y | E9: Annual | F9: 1980 | G9: 1584
A10: CFQ7TTC0HL8Z | B10: 5 | C10: 10-Year Audit Log Retention Add On for FLW | D10: P1Y | E10: Monthly | F10: 1386 | G10: 1108.8
A11: CFQ7TTC0HL8Z | B11: 4 | C11: 10-Year Audit Log Retention Add On (Education Pricing) | D11: P1Y | E11: Annual | F11: 1980 | G11: 1584
A12: CFQ7TTC0HL8Z | B12: 5 | C12: 10-Year Audit Log Retention Add On for FLW | D12: P1Y | E12: Annual | F12: 1320 | G12: 1056
A13: CFQ7TTC0HL8Z | B13: 1 | C13: 10-Year Audit Log Retention Add On | D13: P1M | E13: Monthly | F13: 198 | G13: 158.4
A14: CFQ7TTC0HL8Z | B14: 4 | C14: 10-Year Audit Log Retention Add On (Education Pricing) | D14: P1M | E14: Monthly | F14: 198 | G14: 158.4
A15: CFQ7TTC0HL8Z | B15: 5 | C15: 10-Year Audit Log Retention Add On for FLW | D15: P1M | E15: Monthly | F15: 132 | G15: 105.6
A16: CFQ7TTC0HL8Z | B16: 4 | C16: 10-Year Audit Log Retention Add On (Education Pricing) | D16: P1Y | E16: Monthly | F16: 2079 | G16: 1663.2
A17: CFQ7TTC0RN26 | B17: 1 | C17: Advanced Data Residency | D17: P1Y | E17: Monthly | F17: 2079 | G17: 1663.2
A18: CFQ7TTC0RN26 | B18: 1 | C18: Advanced Data Residency | D18: P3Y | E18: Triennial | F18: 5940 | G18: 4752
A19: CFQ7TTC0RN26 | B19: 1 | C19: Advanced Data Residency | D19: P1Y | E19: Annual | F19: 1980 | G19: 1584
A20: CFQ7TTC0RN26 | B20: 1 | C20: Advanced Data Residency | D20: P3Y | E20: Annual | F20: 5940 | G20: 4752
A21: CFQ7TTC0HDK0 | B21: 000B | C21: Advanced Communications (Non-Profit Pricing) | D21: P1Y | E21: Monthly | F21: 5040 | G21: 4536
A22: CFQ7TTC0HDK0 | B22: 000D | C22: Advanced Communications (Education Student Pricing) | D22: P1Y | E22: Monthly | F22: 1890 | G22: 1512
A23: CFQ7TTC0HDK0 | B23: 000C | C23: Advanced Communications (Education Faculty Pricing) | D23: P1Y | E23: Monthly | F23: 2520 | G23: 2016
A24: CFQ7TTC0HDK0 | B24: 000C | C24: Advanced Communications (Education Faculty Pricing) | D24: P1Y | E24: Annual | F24: 2400 | G24: 1920
A25: CFQ7TTC0HDK0 | B25: 000B | C25: Advanced Communications (Non-Profit Pricing) | D25: P1M | E25: Monthly | F25: 480 | G25: 432
A26: CFQ7TTC0HDK0 | B26: 000D | C26: Advanced Communications (Education Student Pricing) | D26: P1M | E26: Monthly | F26: 180 | G26: 144
A27: CFQ7TTC0HDK0 | B27: 1 | C27: Advanced Communications | D27: P1M | E27: Monthly | F27: 1200 | G27: 960
A28: CFQ7TTC0HDK0 | B28: 000B | C28: Advanced Communications (Non-Profit Pricing) | D28: P1Y | E28: Annual | F28: 4800 | G28: 4320
A29: CFQ7TTC0HDK0 | B29: 1 | C29: Advanced Communications | D29: P1Y | E29: Annual | F29: 12000 | G29: 9600
A30: CFQ7TTC0HDK0 | B30: 1 | C30: Advanced Communications | D30: P1Y | E30: Monthly | F30: 12600 | G30: 10080
A31: CFQ7TTC0HDK0 | B31: 000D | C31: Advanced Communications (Education Student Pricing) | D31: P1Y | E31: Annual | F31: 1800 | G31: 1440
A32: CFQ7TTC0HDK0 | B32: 000C | C32: Advanced Communications (Education Faculty Pricing) | D32: P1M | E32: Monthly | F32: 240 | G32: 192
A33: CFQ7TTC0LHQD | B33: 4 | C33: Advanced eDiscovery Storage (Education Faculty Pricing) | D33: P1M | E33: Monthly | F33: 1998 | G33: 1598.4
A34: CFQ7TTC0LHQD | B34: 4 | C34: Advanced eDiscovery Storage (Education Faculty Pricing) | D34: P1Y | E34: Monthly | F34: 20979 | G34: 16783.2
A35: CFQ7TTC0LHQD | B35: 4 | C35: Advanced eDiscovery Storage (Education Faculty Pricing) | D35: P1Y | E35: Annual | F35: 19980 | G35: 15984
A36: CFQ7TTC0LHQD | B36: 1 | C36: Advanced eDiscovery Storage | D36: P1Y | E36: Monthly | F36: 104832 | G36: 83865.6
A37: CFQ7TTC0LHQD | B37: 5 | C37: Advanced eDiscovery Storage (Non-Profit Pricing) | D37: P1Y | E37: Monthly | F37: 41958 | G37: 37762.2
A38: CFQ7TTC0LHQD | B38: 1 | C38: Advanced eDiscovery Storage | D38: P1Y | E38: Annual | F38: 99840 | G38: 79872
A39: CFQ7TTC0LHQD | B39: 5 | C39: Advanced eDiscovery Storage (Non-Profit Pricing) | D39: P1M | E39: Monthly | F39: 3996 | G39: 3596.4
A40: CFQ7TTC0LHQD | B40: 5 | C40: Advanced eDiscovery Storage (Non-Profit Pricing) | D40: P1Y | E40: Annual | F40: 39960 | G40: 35964
A41: CFQ7TTC0LHQD | B41: 1 | C41: Advanced eDiscovery Storage | D41: P1M | E41: Monthly | F41: 9984 | G41: 7987.2
A42: CFQ7TTC10RSN | B42: 3 | C42: Microsoft Defender and Purview Suites for Microsoft 365 Business Premium | D42: P1Y | E42: Monthly | F42: 15750 | G42: 12600
A43: CFQ7TTC10RSN | B43: 1 | C43: Microsoft Defender Suite for Microsoft 365 Business Premium | D43: P1Y | E43: Monthly | F43: 10458 | G43: 8366.4
...

Sheet Calculation Sheet
A2: ProductId | B2: SkuId | C2: SkuTitle | D2: TermDuration | E2: BillingPlan | F2: Segment | G2: ERP Price | H2: UnitPrice | I2: M365 CSP Core Rebate (Disti) | J2: Distributor Product Tier 1 | K2: Distributor Product Tier 2 | L2: Distributor Growth Accelerator | M2: Expected Disti Discounting to Skysecure | N2: Expected Disti Pricing to Skysecure
A3: CFQ7TTC0HL8Z | B3: 1 | C3: 10-Year Audit Log Retention Add On | D3: P1Y | E3: Monthly | F3: Commercial | G3: 2079 | H3: 1663.2 | I3: =IF(COUNTIFS(Addendum!C:C,A3,Addendum!D:D,IF(ISNUMBER(B3),TEXT(B3,"0000"),B3),Addendum!E:E,"X")>0,4%,0) -> 0.04 | J3: =IF(COUNTIFS(Addendum!C:C,A3,Addendum!D:D,IF(ISNUMBER(B3),TEXT(B3,"0000"),B3),Addendum!F:F,"X")>0,2.5%,0) -> 0 | K3: =IF(COUNTIFS(Addendum!C:C,A3,Addendum!D:D,IF(ISNUMBER(B3),TEXT(B3,"0000"),B3),Addendum!G:G,"X")>0,7%,0) -> 0 | L3: =IF(COUNTIFS(Addendum!C:C,A3,Addendum!D:D,IF(ISNUMBER(B3),TEXT(B3,"0000"),B3),Addendum!I:I,"X")>0,10%,0) -> 0 | M3: =IF(AND(I3=0%,J3=0%,K3=0%,L3=0%),0%, IF(OR(TRIM(E3)="OneTime",TRIM(D3)=""),0%, IF( OR( TRIM(D3)="P1M", AND(TRIM(D3)="P1Y",TRIM(E3)="Monthly"), AND(TRIM(D3)="P3Y",TRIM(E3)="Monthly") ), IF(AND(I3=4%,J3=0%,K3=0%,L3=0%),1%, IF(AND(I3=4%,J3=2.5%,K3=0%,L3=10%),2%, IF(AND(I3=4%,J3=0%,K3=7%,L3=10%),3%,0%))), IF( OR( AND(TRIM(D3)="P1Y",TRIM(E3)="Annual"), AND(TRIM(D3)="P3Y",TRIM(E3)="Annual"), AND(TRIM(D3)="P3Y",TRIM(E3)="Triennial") ), IF(AND(I3=4%,J3=0%,K3=0%,L3=0%),3%, IF(AND(I3=4%,J3=2.5%,K3=0%,L3=10%),10%, IF(AND(I3=4%,J3=0%,K3=7%,L3=10%),14%,0%))), 0% )))) -> 0.01 | N3: =H3-(H3*M3) -> 1646.568
A4: CFQ7TTC0HL8Z | B4: 1 | C4: 10-Year Audit Log Retention Add On | D4: P1Y | E4: Annual | F4: Commercial | G4: 1980 | H4: 1584 | I4: =IF(COUNTIFS(Addendum!C:C,A4,Addendum!D:D,IF(ISNUMBER(B4),TEXT(B4,"0000"),B4),Addendum!E:E,"X")>0,4%,0) -> 0.04 | J4: =IF(COUNTIFS(Addendum!C:C,A4,Addendum!D:D,IF(ISNUMBER(B4),TEXT(B4,"0000"),B4),Addendum!F:F,"X")>0,2.5%,0) -> 0 | K4: =IF(COUNTIFS(Addendum!C:C,A4,Addendum!D:D,IF(ISNUMBER(B4),TEXT(B4,"0000"),B4),Addendum!G:G,"X")>0,7%,0) -> 0 | L4: =IF(COUNTIFS(Addendum!C:C,A4,Addendum!D:D,IF(ISNUMBER(B4),TEXT(B4,"0000"),B4),Addendum!I:I,"X")>0,10%,0) -> 0 | M4: =IF(AND(I4=0%,J4=0%,K4=0%,L4=0%),0%, IF(OR(TRIM(E4)="OneTime",TRIM(D4)=""),0%, IF( OR( TRIM(D4)="P1M", AND(TRIM(D4)="P1Y",TRIM(E4)="Monthly"), AND(TRIM(D4)="P3Y",TRIM(E4)="Monthly") ), IF(AND(I4=4%,J4=0%,K4=0%,L4=0%),1%, IF(AND(I4=4%,J4=2.5%,K4=0%,L4=10%),2%, IF(AND(I4=4%,J4=0%,K4=7%,L4=10%),3%,0%))), IF( OR( AND(TRIM(D4)="P1Y",TRIM(E4)="Annual"), AND(TRIM(D4)="P3Y",TRIM(E4)="Annual"), AND(TRIM(D4)="P3Y",TRIM(E4)="Triennial") ), IF(AND(I4=4%,J4=0%,K4=0%,L4=0%),3%, IF(AND(I4=4%,J4=2.5%,K4=0%,L4=10%),10%, IF(AND(I4=4%,J4=0%,K4=7%,L4=10%),14%,0%))), 0% )))) -> 0.03 | N4: =H4-(H4*M4) -> 1536.48
A5: CFQ7TTC0HL8Z | B5: 5 | C5: 10-Year Audit Log Retention Add On for FLW | D5: P1Y | E5: Monthly | F5: Commercial | G5: 1386 | H5: 1108.8 | I5: =IF(COUNTIFS(Addendum!C:C,A5,Addendum!D:D,IF(ISNUMBER(B5),TEXT(B5,"0000"),B5),Addendum!E:E,"X")>0,4%,0) -> 0.04 | J5: =IF(COUNTIFS(Addendum!C:C,A5,Addendum!D:D,IF(ISNUMBER(B5),TEXT(B5,"0000"),B5),Addendum!F:F,"X")>0,2.5%,0) -> 0 | K5: =IF(COUNTIFS(Addendum!C:C,A5,Addendum!D:D,IF(ISNUMBER(B5),TEXT(B5,"0000"),B5),Addendum!G:G,"X")>0,7%,0) -> 0 | L5: =IF(COUNTIFS(Addendum!C:C,A5,Addendum!D:D,IF(ISNUMBER(B5),TEXT(B5,"0000"),B5),Addendum!I:I,"X")>0,10%,0) -> 0 | M5: =IF(AND(I5=0%,J5=0%,K5=0%,L5=0%),0%, IF(OR(TRIM(E5)="OneTime",TRIM(D5)=""),0%, IF( OR( TRIM(D5)="P1M", AND(TRIM(D5)="P1Y",TRIM(E5)="Monthly"), AND(TRIM(D5)="P3Y",TRIM(E5)="Monthly") ), IF(AND(I5=4%,J5=0%,K5=0%,L5=0%),1%, IF(AND(I5=4%,J5=2.5%,K5=0%,L5=10%),2%, IF(AND(I5=4%,J5=0%,K5=7%,L5=10%),3%,0%))), IF( OR( AND(TRIM(D5)="P1Y",TRIM(E5)="Annual"), AND(TRIM(D5)="P3Y",TRIM(E5)="Annual"), AND(TRIM(D5)="P3Y",TRIM(E5)="Triennial") ), IF(AND(I5=4%,J5=0%,K5=0%,L5=0%),3%, IF(AND(I5=4%,J5=2.5%,K5=0%,L5=10%),10%, IF(AND(I5=4%,J5=0%,K5=7%,L5=10%),14%,0%))), 0% )))) -> 0.01 | N5: =H5-(H5*M5) -> 1097.712
A6: CFQ7TTC0HL8Z | B6: 4 | C6: 10-Year Audit Log Retention Add On (Education Pricing) | D6: P1Y | E6: Annual | F6: Education | G6: 1980 | H6: 1584 | I6: =IF(COUNTIFS(Addendum!C:C,A6,Addendum!D:D,IF(ISNUMBER(B6),TEXT(B6,"0000"),B6),Addendum!E:E,"X")>0,4%,0) -> 0.04 | J6: =IF(COUNTIFS(Addendum!C:C,A6,Addendum!D:D,IF(ISNUMBER(B6),TEXT(B6,"0000"),B6),Addendum!F:F,"X")>0,2.5%,0) -> 0 | K6: =IF(COUNTIFS(Addendum!C:C,A6,Addendum!D:D,IF(ISNUMBER(B6),TEXT(B6,"0000"),B6),Addendum!G:G,"X")>0,7%,0) -> 0 | L6: =IF(COUNTIFS(Addendum!C:C,A6,Addendum!D:D,IF(ISNUMBER(B6),TEXT(B6,"0000"),B6),Addendum!I:I,"X")>0,10%,0) -> 0 | M6: =IF(AND(I6=0%,J6=0%,K6=0%,L6=0%),0%, IF(OR(TRIM(E6)="OneTime",TRIM(D6)=""),0%, IF( OR( TRIM(D6)="P1M", AND(TRIM(D6)="P1Y",TRIM(E6)="Monthly"), AND(TRIM(D6)="P3Y",TRIM(E6)="Monthly") ), IF(AND(I6=4%,J6=0%,K6=0%,L6=0%),1%, IF(AND(I6=4%,J6=2.5%,K6=0%,L6=10%),2%, IF(AND(I6=4%,J6=0%,K6=7%,L6=10%),3%,0%))), IF( OR( AND(TRIM(D6)="P1Y",TRIM(E6)="Annual"), AND(TRIM(D6)="P3Y",TRIM(E6)="Annual"), AND(TRIM(D6)="P3Y",TRIM(E6)="Triennial") ), IF(AND(I6=4%,J6=0%,K6=0%,L6=0%),3%, IF(AND(I6=4%,J6=2.5%,K6=0%,L6=10%),10%, IF(AND(I6=4%,J6=0%,K6=7%,L6=10%),14%,0%))), 0% )))) -> 0.03 | N6: =H6-(H6*M6) -> 1536.48
A7: CFQ7TTC0HL8Z | B7: 5 | C7: 10-Year Audit Log Retention Add On for FLW | D7: P1Y | E7: Annual | F7: Commercial | G7: 1320 | H7: 1056 | I7: =IF(COUNTIFS(Addendum!C:C,A7,Addendum!D:D,IF(ISNUMBER(B7),TEXT(B7,"0000"),B7),Addendum!E:E,"X")>0,4%,0) -> 0.04 | J7: =IF(COUNTIFS(Addendum!C:C,A7,Addendum!D:D,IF(ISNUMBER(B7),TEXT(B7,"0000"),B7),Addendum!F:F,"X")>0,2.5%,0) -> 0 | K7: =IF(COUNTIFS(Addendum!C:C,A7,Addendum!D:D,IF(ISNUMBER(B7),TEXT(B7,"0000"),B7),Addendum!G:G,"X")>0,7%,0) -> 0 | L7: =IF(COUNTIFS(Addendum!C:C,A7,Addendum!D:D,IF(ISNUMBER(B7),TEXT(B7,"0000"),B7),Addendum!I:I,"X")>0,10%,0) -> 0 | M7: =IF(AND(I7=0%,J7=0%,K7=0%,L7=0%),0%, IF(OR(TRIM(E7)="OneTime",TRIM(D7)=""),0%, IF( OR( TRIM(D7)="P1M", AND(TRIM(D7)="P1Y",TRIM(E7)="Monthly"), AND(TRIM(D7)="P3Y",TRIM(E7)="Monthly") ), IF(AND(I7=4%,J7=0%,K7=0%,L7=0%),1%, IF(AND(I7=4%,J7=2.5%,K7=0%,L7=10%),2%, IF(AND(I7=4%,J7=0%,K7=7%,L7=10%),3%,0%))), IF( OR( AND(TRIM(D7)="P1Y",TRIM(E7)="Annual"), AND(TRIM(D7)="P3Y",TRIM(E7)="Annual"), AND(TRIM(D7)="P3Y",TRIM(E7)="Triennial") ), IF(AND(I7=4%,J7=0%,K7=0%,L7=0%),3%, IF(AND(I7=4%,J7=2.5%,K7=0%,L7=10%),10%, IF(AND(I7=4%,J7=0%,K7=7%,L7=10%),14%,0%))), 0% )))) -> 0.03 | N7: =H7-(H7*M7) -> 1024.32
A8: CFQ7TTC0HL8Z | B8: 1 | C8: 10-Year Audit Log Retention Add On | D8: P1M | E8: Monthly | F8: Commercial | G8: 198 | H8: 158.4 | I8: =IF(COUNTIFS(Addendum!C:C,A8,Addendum!D:D,IF(ISNUMBER(B8),TEXT(B8,"0000"),B8),Addendum!E:E,"X")>0,4%,0) -> 0.04 | J8: =IF(COUNTIFS(Addendum!C:C,A8,Addendum!D:D,IF(ISNUMBER(B8),TEXT(B8,"0000"),B8),Addendum!F:F,"X")>0,2.5%,0) -> 0 | K8: =IF(COUNTIFS(Addendum!C:C,A8,Addendum!D:D,IF(ISNUMBER(B8),TEXT(B8,"0000"),B8),Addendum!G:G,"X")>0,7%,0) -> 0 | L8: =IF(COUNTIFS(Addendum!C:C,A8,Addendum!D:D,IF(ISNUMBER(B8),TEXT(B8,"0000"),B8),Addendum!I:I,"X")>0,10%,0) -> 0 | M8: =IF(AND(I8=0%,J8=0%,K8=0%,L8=0%),0%, IF(OR(TRIM(E8)="OneTime",TRIM(D8)=""),0%, IF( OR( TRIM(D8)="P1M", AND(TRIM(D8)="P1Y",TRIM(E8)="Monthly"), AND(TRIM(D8)="P3Y",TRIM(E8)="Monthly") ), IF(AND(I8=4%,J8=0%,K8=0%,L8=0%),1%, IF(AND(I8=4%,J8=2.5%,K8=0%,L8=10%),2%, IF(AND(I8=4%,J8=0%,K8=7%,L8=10%),3%,0%))), IF( OR( AND(TRIM(D8)="P1Y",TRIM(E8)="Annual"), AND(TRIM(D8)="P3Y",TRIM(E8)="Annual"), AND(TRIM(D8)="P3Y",TRIM(E8)="Triennial") ), IF(AND(I8=4%,J8=0%,K8=0%,L8=0%),3%, IF(AND(I8=4%,J8=2.5%,K8=0%,L8=10%),10%, IF(AND(I8=4%,J8=0%,K8=7%,L8=10%),14%,0%))), 0% )))) -> 0.01 | N8: =H8-(H8*M8) -> 156.816
A9: CFQ7TTC0HL8Z | B9: 4 | C9: 10-Year Audit Log Retention Add On (Education Pricing) | D9: P1M | E9: Monthly | F9: Education | G9: 198 | H9: 158.4 | I9: =IF(COUNTIFS(Addendum!C:C,A9,Addendum!D:D,IF(ISNUMBER(B9),TEXT(B9,"0000"),B9),Addendum!E:E,"X")>0,4%,0) -> 0.04 | J9: =IF(COUNTIFS(Addendum!C:C,A9,Addendum!D:D,IF(ISNUMBER(B9),TEXT(B9,"0000"),B9),Addendum!F:F,"X")>0,2.5%,0) -> 0 | K9: =IF(COUNTIFS(Addendum!C:C,A9,Addendum!D:D,IF(ISNUMBER(B9),TEXT(B9,"0000"),B9),Addendum!G:G,"X")>0,7%,0) -> 0 | L9: =IF(COUNTIFS(Addendum!C:C,A9,Addendum!D:D,IF(ISNUMBER(B9),TEXT(B9,"0000"),B9),Addendum!I:I,"X")>0,10%,0) -> 0 | M9: =IF(AND(I9=0%,J9=0%,K9=0%,L9=0%),0%, IF(OR(TRIM(E9)="OneTime",TRIM(D9)=""),0%, IF( OR( TRIM(D9)="P1M", AND(TRIM(D9)="P1Y",TRIM(E9)="Monthly"), AND(TRIM(D9)="P3Y",TRIM(E9)="Monthly") ), IF(AND(I9=4%,J9=0%,K9=0%,L9=0%),1%, IF(AND(I9=4%,J9=2.5%,K9=0%,L9=10%),2%, IF(AND(I9=4%,J9=0%,K9=7%,L9=10%),3%,0%))), IF( OR( AND(TRIM(D9)="P1Y",TRIM(E9)="Annual"), AND(TRIM(D9)="P3Y",TRIM(E9)="Annual"), AND(TRIM(D9)="P3Y",TRIM(E9)="Triennial") ), IF(AND(I9=4%,J9=0%,K9=0%,L9=0%),3%, IF(AND(I9=4%,J9=2.5%,K9=0%,L9=10%),10%, IF(AND(I9=4%,J9=0%,K9=7%,L9=10%),14%,0%))), 0% )))) -> 0.01 | N9: =H9-(H9*M9) -> 156.816
A10: CFQ7TTC0HL8Z | B10: 5 | C10: 10-Year Audit Log Retention Add On for FLW | D10: P1M | E10: Monthly | F10: Commercial | G10: 132 | H10: 105.6 | I10: =IF(COUNTIFS(Addendum!C:C,A10,Addendum!D:D,IF(ISNUMBER(B10),TEXT(B10,"0000"),B10),Addendum!E:E,"X")>0,4%,0) -> 0.04 | J10: =IF(COUNTIFS(Addendum!C:C,A10,Addendum!D:D,IF(ISNUMBER(B10),TEXT(B10,"0000"),B10),Addendum!F:F,"X")>0,2.5%,0) -> 0 | K10: =IF(COUNTIFS(Addendum!C:C,A10,Addendum!D:D,IF(ISNUMBER(B10),TEXT(B10,"0000"),B10),Addendum!G:G,"X")>0,7%,0) -> 0 | L10: =IF(COUNTIFS(Addendum!C:C,A10,Addendum!D:D,IF(ISNUMBER(B10),TEXT(B10,"0000"),B10),Addendum!I:I,"X")>0,10%,0) -> 0 | M10: =IF(AND(I10=0%,J10=0%,K10=0%,L10=0%),0%, IF(OR(TRIM(E10)="OneTime",TRIM(D10)=""),0%, IF( OR( TRIM(D10)="P1M", AND(TRIM(D10)="P1Y",TRIM(E10)="Monthly"), AND(TRIM(D10)="P3Y",TRIM(E10)="Monthly") ), IF(AND(I10=4%,J10=0%,K10=0%,L10=0%),1%, IF(AND(I10=4%,J10=2.5%,K10=0%,L10=10%),2%, IF(AND(I10=4%,J10=0%,K10=7%,L10=10%),3%,0%))), IF( OR( AND(TRIM(D10)="P1Y",TRIM(E10)="Annual"), AND(TRIM(D10)="P3Y",TRIM(E10)="Annual"), AND(TRIM(D10)="P3Y",TRIM(E10)="Triennial") ), IF(AND(I10=4%,J10=0%,K10=0%,L10=0%),3%, IF(AND(I10=4%,J10=2.5%,K10=0%,L10=10%),10%, IF(AND(I10=4%,J10=0%,K10=7%,L10=10%),14%,0%))), 0% )))) -> 0.01 | N10: =H10-(H10*M10) -> 104.544
A11: CFQ7TTC0HL8Z | B11: 4 | C11: 10-Year Audit Log Retention Add On (Education Pricing) | D11: P1Y | E11: Monthly | F11: Education | G11: 2079 | H11: 1663.2 | I11: =IF(COUNTIFS(Addendum!C:C,A11,Addendum!D:D,IF(ISNUMBER(B11),TEXT(B11,"0000"),B11),Addendum!E:E,"X")>0,4%,0) -> 0.04 | J11: =IF(COUNTIFS(Addendum!C:C,A11,Addendum!D:D,IF(ISNUMBER(B11),TEXT(B11,"0000"),B11),Addendum!F:F,"X")>0,2.5%,0) -> 0 | K11: =IF(COUNTIFS(Addendum!C:C,A11,Addendum!D:D,IF(ISNUMBER(B11),TEXT(B11,"0000"),B11),Addendum!G:G,"X")>0,7%,0) -> 0 | L11: =IF(COUNTIFS(Addendum!C:C,A11,Addendum!D:D,IF(ISNUMBER(B11),TEXT(B11,"0000"),B11),Addendum!I:I,"X")>0,10%,0) -> 0 | M11: =IF(AND(I11=0%,J11=0%,K11=0%,L11=0%),0%, IF(OR(TRIM(E11)="OneTime",TRIM(D11)=""),0%, IF( OR( TRIM(D11)="P1M", AND(TRIM(D11)="P1Y",TRIM(E11)="Monthly"), AND(TRIM(D11)="P3Y",TRIM(E11)="Monthly") ), IF(AND(I11=4%,J11=0%,K11=0%,L11=0%),1%, IF(AND(I11=4%,J11=2.5%,K11=0%,L11=10%),2%, IF(AND(I11=4%,J11=0%,K11=7%,L11=10%),3%,0%))), IF( OR( AND(TRIM(D11)="P1Y",TRIM(E11)="Annual"), AND(TRIM(D11)="P3Y",TRIM(E11)="Annual"), AND(TRIM(D11)="P3Y",TRIM(E11)="Triennial") ), IF(AND(I11=4%,J11=0%,K11=0%,L11=0%),3%, IF(AND(I11=4%,J11=2.5%,K11=0%,L11=10%),10%, IF(AND(I11=4%,J11=0%,K11=7%,L11=10%),14%,0%))), 0% )))) -> 0.01 | N11: =H11-(H11*M11) -> 1646.568
A12: CFQ7TTC0RN26 | B12: 1 | C12: Advanced Data Residency | D12: P1Y | E12: Monthly | F12: Commercial | G12: 2079 | H12: 1663.2 | I12: =IF(COUNTIFS(Addendum!C:C,A12,Addendum!D:D,IF(ISNUMBER(B12),TEXT(B12,"0000"),B12),Addendum!E:E,"X")>0,4%,0) -> 0 | J12: =IF(COUNTIFS(Addendum!C:C,A12,Addendum!D:D,IF(ISNUMBER(B12),TEXT(B12,"0000"),B12),Addendum!F:F,"X")>0,2.5%,0) -> 0 | K12: =IF(COUNTIFS(Addendum!C:C,A12,Addendum!D:D,IF(ISNUMBER(B12),TEXT(B12,"0000"),B12),Addendum!G:G,"X")>0,7%,0) -> 0 | L12: =IF(COUNTIFS(Addendum!C:C,A12,Addendum!D:D,IF(ISNUMBER(B12),TEXT(B12,"0000"),B12),Addendum!I:I,"X")>0,10%,0) -> 0 | M12: =IF(AND(I12=0%,J12=0%,K12=0%,L12=0%),0%, IF(OR(TRIM(E12)="OneTime",TRIM(D12)=""),0%, IF( OR( TRIM(D12)="P1M", AND(TRIM(D12)="P1Y",TRIM(E12)="Monthly"), AND(TRIM(D12)="P3Y",TRIM(E12)="Monthly") ), IF(AND(I12=4%,J12=0%,K12=0%,L12=0%),1%, IF(AND(I12=4%,J12=2.5%,K12=0%,L12=10%),2%, IF(AND(I12=4%,J12=0%,K12=7%,L12=10%),3%,0%))), IF( OR( AND(TRIM(D12)="P1Y",TRIM(E12)="Annual"), AND(TRIM(D12)="P3Y",TRIM(E12)="Annual"), AND(TRIM(D12)="P3Y",TRIM(E12)="Triennial") ), IF(AND(I12=4%,J12=0%,K12=0%,L12=0%),3%, IF(AND(I12=4%,J12=2.5%,K12=0%,L12=10%),10%, IF(AND(I12=4%,J12=0%,K12=7%,L12=10%),14%,0%))), 0% )))) -> 0 | N12: =H12-(H12*M12) -> 1663.2
A13: CFQ7TTC0RN26 | B13: 1 | C13: Advanced Data Residency | D13: P3Y | E13: Triennial | F13: Commercial | G13: 5940 | H13: 4752 | I13: =IF(COUNTIFS(Addendum!C:C,A13,Addendum!D:D,IF(ISNUMBER(B13),TEXT(B13,"0000"),B13),Addendum!E:E,"X")>0,4%,0) -> 0 | J13: =IF(COUNTIFS(Addendum!C:C,A13,Addendum!D:D,IF(ISNUMBER(B13),TEXT(B13,"0000"),B13),Addendum!F:F,"X")>0,2.5%,0) -> 0 | K13: =IF(COUNTIFS(Addendum!C:C,A13,Addendum!D:D,IF(ISNUMBER(B13),TEXT(B13,"0000"),B13),Addendum!G:G,"X")>0,7%,0) -> 0 | L13: =IF(COUNTIFS(Addendum!C:C,A13,Addendum!D:D,IF(ISNUMBER(B13),TEXT(B13,"0000"),B13),Addendum!I:I,"X")>0,10%,0) -> 0 | M13: =IF(AND(I13=0%,J13=0%,K13=0%,L13=0%),0%, IF(OR(TRIM(E13)="OneTime",TRIM(D13)=""),0%, IF( OR( TRIM(D13)="P1M", AND(TRIM(D13)="P1Y",TRIM(E13)="Monthly"), AND(TRIM(D13)="P3Y",TRIM(E13)="Monthly") ), IF(AND(I13=4%,J13=0%,K13=0%,L13=0%),1%, IF(AND(I13=4%,J13=2.5%,K13=0%,L13=10%),2%, IF(AND(I13=4%,J13=0%,K13=7%,L13=10%),3%,0%))), IF( OR( AND(TRIM(D13)="P1Y",TRIM(E13)="Annual"), AND(TRIM(D13)="P3Y",TRIM(E13)="Annual"), AND(TRIM(D13)="P3Y",TRIM(E13)="Triennial") ), IF(AND(I13=4%,J13=0%,K13=0%,L13=0%),3%, IF(AND(I13=4%,J13=2.5%,K13=0%,L13=10%),10%, IF(AND(I13=4%,J13=0%,K13=7%,L13=10%),14%,0%))), 0% )))) -> 0 | N13: =H13-(H13*M13) -> 4752
A14: CFQ7TTC0RN26 | B14: 1 | C14: Advanced Data Residency | D14: P1Y | E14: Annual | F14: Commercial | G14: 1980 | H14: 1584 | I14: =IF(COUNTIFS(Addendum!C:C,A14,Addendum!D:D,IF(ISNUMBER(B14),TEXT(B14,"0000"),B14),Addendum!E:E,"X")>0,4%,0) -> 0 | J14: =IF(COUNTIFS(Addendum!C:C,A14,Addendum!D:D,IF(ISNUMBER(B14),TEXT(B14,"0000"),B14),Addendum!F:F,"X")>0,2.5%,0) -> 0 | K14: =IF(COUNTIFS(Addendum!C:C,A14,Addendum!D:D,IF(ISNUMBER(B14),TEXT(B14,"0000"),B14),Addendum!G:G,"X")>0,7%,0) -> 0 | L14: =IF(COUNTIFS(Addendum!C:C,A14,Addendum!D:D,IF(ISNUMBER(B14),TEXT(B14,"0000"),B14),Addendum!I:I,"X")>0,10%,0) -> 0 | M14: =IF(AND(I14=0%,J14=0%,K14=0%,L14=0%),0%, IF(OR(TRIM(E14)="OneTime",TRIM(D14)=""),0%, IF( OR( TRIM(D14)="P1M", AND(TRIM(D14)="P1Y",TRIM(E14)="Monthly"), AND(TRIM(D14)="P3Y",TRIM(E14)="Monthly") ), IF(AND(I14=4%,J14=0%,K14=0%,L14=0%),1%, IF(AND(I14=4%,J14=2.5%,K14=0%,L14=10%),2%, IF(AND(I14=4%,J14=0%,K14=7%,L14=10%),3%,0%))), IF( OR( AND(TRIM(D14)="P1Y",TRIM(E14)="Annual"), AND(TRIM(D14)="P3Y",TRIM(E14)="Annual"), AND(TRIM(D14)="P3Y",TRIM(E14)="Triennial") ), IF(AND(I14=4%,J14=0%,K14=0%,L14=0%),3%, IF(AND(I14=4%,J14=2.5%,K14=0%,L14=10%),10%, IF(AND(I14=4%,J14=0%,K14=7%,L14=10%),14%,0%))), 0% )))) -> 0 | N14: =H14-(H14*M14) -> 1584
A15: CFQ7TTC0RN26 | B15: 1 | C15: Advanced Data Residency | D15: P3Y | E15: Annual | F15: Commercial | G15: 5940 | H15: 4752 | I15: =IF(COUNTIFS(Addendum!C:C,A15,Addendum!D:D,IF(ISNUMBER(B15),TEXT(B15,"0000"),B15),Addendum!E:E,"X")>0,4%,0) -> 0 | J15: =IF(COUNTIFS(Addendum!C:C,A15,Addendum!D:D,IF(ISNUMBER(B15),TEXT(B15,"0000"),B15),Addendum!F:F,"X")>0,2.5%,0) -> 0 | K15: =IF(COUNTIFS(Addendum!C:C,A15,Addendum!D:D,IF(ISNUMBER(B15),TEXT(B15,"0000"),B15),Addendum!G:G,"X")>0,7%,0) -> 0 | L15: =IF(COUNTIFS(Addendum!C:C,A15,Addendum!D:D,IF(ISNUMBER(B15),TEXT(B15,"0000"),B15),Addendum!I:I,"X")>0,10%,0) -> 0 | M15: =IF(AND(I15=0%,J15=0%,K15=0%,L15=0%),0%, IF(OR(TRIM(E15)="OneTime",TRIM(D15)=""),0%, IF( OR( TRIM(D15)="P1M", AND(TRIM(D15)="P1Y",TRIM(E15)="Monthly"), AND(TRIM(D15)="P3Y",TRIM(E15)="Monthly") ), IF(AND(I15=4%,J15=0%,K15=0%,L15=0%),1%, IF(AND(I15=4%,J15=2.5%,K15=0%,L15=10%),2%, IF(AND(I15=4%,J15=0%,K15=7%,L15=10%),3%,0%))), IF( OR( AND(TRIM(D15)="P1Y",TRIM(E15)="Annual"), AND(TRIM(D15)="P3Y",TRIM(E15)="Annual"), AND(TRIM(D15)="P3Y",TRIM(E15)="Triennial") ), IF(AND(I15=4%,J15=0%,K15=0%,L15=0%),3%, IF(AND(I15=4%,J15=2.5%,K15=0%,L15=10%),10%, IF(AND(I15=4%,J15=0%,K15=7%,L15=10%),14%,0%))), 0% )))) -> 0 | N15: =H15-(H15*M15) -> 4752
A16: CFQ7TTC0HDK0 | B16: 000B | C16: Advanced Communications (Non-Profit Pricing) | D16: P1Y | E16: Monthly | F16: Charity | G16: 5040 | H16: 4536 | I16: =IF(COUNTIFS(Addendum!C:C,A16,Addendum!D:D,IF(ISNUMBER(B16),TEXT(B16,"0000"),B16),Addendum!E:E,"X")>0,4%,0) -> 0.04 | J16: =IF(COUNTIFS(Addendum!C:C,A16,Addendum!D:D,IF(ISNUMBER(B16),TEXT(B16,"0000"),B16),Addendum!F:F,"X")>0,2.5%,0) -> 0 | K16: =IF(COUNTIFS(Addendum!C:C,A16,Addendum!D:D,IF(ISNUMBER(B16),TEXT(B16,"0000"),B16),Addendum!G:G,"X")>0,7%,0) -> 0 | L16: =IF(COUNTIFS(Addendum!C:C,A16,Addendum!D:D,IF(ISNUMBER(B16),TEXT(B16,"0000"),B16),Addendum!I:I,"X")>0,10%,0) -> 0 | M16: =IF(AND(I16=0%,J16=0%,K16=0%,L16=0%),0%, IF(OR(TRIM(E16)="OneTime",TRIM(D16)=""),0%, IF( OR( TRIM(D16)="P1M", AND(TRIM(D16)="P1Y",TRIM(E16)="Monthly"), AND(TRIM(D16)="P3Y",TRIM(E16)="Monthly") ), IF(AND(I16=4%,J16=0%,K16=0%,L16=0%),1%, IF(AND(I16=4%,J16=2.5%,K16=0%,L16=10%),2%, IF(AND(I16=4%,J16=0%,K16=7%,L16=10%),3%,0%))), IF( OR( AND(TRIM(D16)="P1Y",TRIM(E16)="Annual"), AND(TRIM(D16)="P3Y",TRIM(E16)="Annual"), AND(TRIM(D16)="P3Y",TRIM(E16)="Triennial") ), IF(AND(I16=4%,J16=0%,K16=0%,L16=0%),3%, IF(AND(I16=4%,J16=2.5%,K16=0%,L16=10%),10%, IF(AND(I16=4%,J16=0%,K16=7%,L16=10%),14%,0%))), 0% )))) -> 0.01 | N16: =H16-(H16*M16) -> 4490.64
A17: CFQ7TTC0HDK0 | B17: 000D | C17: Advanced Communications (Education Student Pricing) | D17: P1Y | E17: Monthly | F17: Education | G17: 1890 | H17: 1512 | I17: =IF(COUNTIFS(Addendum!C:C,A17,Addendum!D:D,IF(ISNUMBER(B17),TEXT(B17,"0000"),B17),Addendum!E:E,"X")>0,4%,0) -> 0.04 | J17: =IF(COUNTIFS(Addendum!C:C,A17,Addendum!D:D,IF(ISNUMBER(B17),TEXT(B17,"0000"),B17),Addendum!F:F,"X")>0,2.5%,0) -> 0 | K17: =IF(COUNTIFS(Addendum!C:C,A17,Addendum!D:D,IF(ISNUMBER(B17),TEXT(B17,"0000"),B17),Addendum!G:G,"X")>0,7%,0) -> 0 | L17: =IF(COUNTIFS(Addendum!C:C,A17,Addendum!D:D,IF(ISNUMBER(B17),TEXT(B17,"0000"),B17),Addendum!I:I,"X")>0,10%,0) -> 0 | M17: =IF(AND(I17=0%,J17=0%,K17=0%,L17=0%),0%, IF(OR(TRIM(E17)="OneTime",TRIM(D17)=""),0%, IF( OR( TRIM(D17)="P1M", AND(TRIM(D17)="P1Y",TRIM(E17)="Monthly"), AND(TRIM(D17)="P3Y",TRIM(E17)="Monthly") ), IF(AND(I17=4%,J17=0%,K17=0%,L17=0%),1%, IF(AND(I17=4%,J17=2.5%,K17=0%,L17=10%),2%, IF(AND(I17=4%,J17=0%,K17=7%,L17=10%),3%,0%))), IF( OR( AND(TRIM(D17)="P1Y",TRIM(E17)="Annual"), AND(TRIM(D17)="P3Y",TRIM(E17)="Annual"), AND(TRIM(D17)="P3Y",TRIM(E17)="Triennial") ), IF(AND(I17=4%,J17=0%,K17=0%,L17=0%),3%, IF(AND(I17=4%,J17=2.5%,K17=0%,L17=10%),10%, IF(AND(I17=4%,J17=0%,K17=7%,L17=10%),14%,0%))), 0% )))) -> 0.01 | N17: =H17-(H17*M17) -> 1496.88
A18: CFQ7TTC0HDK0 | B18: 000C | C18: Advanced Communications (Education Faculty Pricing) | D18: P1Y | E18: Monthly | F18: Education | G18: 2520 | H18: 2016 | I18: =IF(COUNTIFS(Addendum!C:C,A18,Addendum!D:D,IF(ISNUMBER(B18),TEXT(B18,"0000"),B18),Addendum!E:E,"X")>0,4%,0) -> 0.04 | J18: =IF(COUNTIFS(Addendum!C:C,A18,Addendum!D:D,IF(ISNUMBER(B18),TEXT(B18,"0000"),B18),Addendum!F:F,"X")>0,2.5%,0) -> 0 | K18: =IF(COUNTIFS(Addendum!C:C,A18,Addendum!D:D,IF(ISNUMBER(B18),TEXT(B18,"0000"),B18),Addendum!G:G,"X")>0,7%,0) -> 0 | L18: =IF(COUNTIFS(Addendum!C:C,A18,Addendum!D:D,IF(ISNUMBER(B18),TEXT(B18,"0000"),B18),Addendum!I:I,"X")>0,10%,0) -> 0 | M18: =IF(AND(I18=0%,J18=0%,K18=0%,L18=0%),0%, IF(OR(TRIM(E18)="OneTime",TRIM(D18)=""),0%, IF( OR( TRIM(D18)="P1M", AND(TRIM(D18)="P1Y",TRIM(E18)="Monthly"), AND(TRIM(D18)="P3Y",TRIM(E18)="Monthly") ), IF(AND(I18=4%,J18=0%,K18=0%,L18=0%),1%, IF(AND(I18=4%,J18=2.5%,K18=0%,L18=10%),2%, IF(AND(I18=4%,J18=0%,K18=7%,L18=10%),3%,0%))), IF( OR( AND(TRIM(D18)="P1Y",TRIM(E18)="Annual"), AND(TRIM(D18)="P3Y",TRIM(E18)="Annual"), AND(TRIM(D18)="P3Y",TRIM(E18)="Triennial") ), IF(AND(I18=4%,J18=0%,K18=0%,L18=0%),3%, IF(AND(I18=4%,J18=2.5%,K18=0%,L18=10%),10%, IF(AND(I18=4%,J18=0%,K18=7%,L18=10%),14%,0%))), 0% )))) -> 0.01 | N18: =H18-(H18*M18) -> 1995.84
A19: CFQ7TTC0HDK0 | B19: 000C | C19: Advanced Communications (Education Faculty Pricing) | D19: P1Y | E19: Annual | F19: Education | G19: 2400 | H19: 1920 | I19: =IF(COUNTIFS(Addendum!C:C,A19,Addendum!D:D,IF(ISNUMBER(B19),TEXT(B19,"0000"),B19),Addendum!E:E,"X")>0,4%,0) -> 0.04 | J19: =IF(COUNTIFS(Addendum!C:C,A19,Addendum!D:D,IF(ISNUMBER(B19),TEXT(B19,"0000"),B19),Addendum!F:F,"X")>0,2.5%,0) -> 0 | K19: =IF(COUNTIFS(Addendum!C:C,A19,Addendum!D:D,IF(ISNUMBER(B19),TEXT(B19,"0000"),B19),Addendum!G:G,"X")>0,7%,0) -> 0 | L19: =IF(COUNTIFS(Addendum!C:C,A19,Addendum!D:D,IF(ISNUMBER(B19),TEXT(B19,"0000"),B19),Addendum!I:I,"X")>0,10%,0) -> 0 | M19: =IF(AND(I19=0%,J19=0%,K19=0%,L19=0%),0%, IF(OR(TRIM(E19)="OneTime",TRIM(D19)=""),0%, IF( OR( TRIM(D19)="P1M", AND(TRIM(D19)="P1Y",TRIM(E19)="Monthly"), AND(TRIM(D19)="P3Y",TRIM(E19)="Monthly") ), IF(AND(I19=4%,J19=0%,K19=0%,L19=0%),1%, IF(AND(I19=4%,J19=2.5%,K19=0%,L19=10%),2%, IF(AND(I19=4%,J19=0%,K19=7%,L19=10%),3%,0%))), IF( OR( AND(TRIM(D19)="P1Y",TRIM(E19)="Annual"), AND(TRIM(D19)="P3Y",TRIM(E19)="Annual"), AND(TRIM(D19)="P3Y",TRIM(E19)="Triennial") ), IF(AND(I19=4%,J19=0%,K19=0%,L19=0%),3%, IF(AND(I19=4%,J19=2.5%,K19=0%,L19=10%),10%, IF(AND(I19=4%,J19=0%,K19=7%,L19=10%),14%,0%))), 0% )))) -> 0.03 | N19: =H19-(H19*M19) -> 1862.4
A20: CFQ7TTC0HDK0 | B20: 000B | C20: Advanced Communications (Non-Profit Pricing) | D20: P1M | E20: Monthly | F20: Charity | G20: 480 | H20: 432 | I20: =IF(COUNTIFS(Addendum!C:C,A20,Addendum!D:D,IF(ISNUMBER(B20),TEXT(B20,"0000"),B20),Addendum!E:E,"X")>0,4%,0) -> 0.04 | J20: =IF(COUNTIFS(Addendum!C:C,A20,Addendum!D:D,IF(ISNUMBER(B20),TEXT(B20,"0000"),B20),Addendum!F:F,"X")>0,2.5%,0) -> 0 | K20: =IF(COUNTIFS(Addendum!C:C,A20,Addendum!D:D,IF(ISNUMBER(B20),TEXT(B20,"0000"),B20),Addendum!G:G,"X")>0,7%,0) -> 0 | L20: =IF(COUNTIFS(Addendum!C:C,A20,Addendum!D:D,IF(ISNUMBER(B20),TEXT(B20,"0000"),B20),Addendum!I:I,"X")>0,10%,0) -> 0 | M20: =IF(AND(I20=0%,J20=0%,K20=0%,L20=0%),0%, IF(OR(TRIM(E20)="OneTime",TRIM(D20)=""),0%, IF( OR( TRIM(D20)="P1M", AND(TRIM(D20)="P1Y",TRIM(E20)="Monthly"), AND(TRIM(D20)="P3Y",TRIM(E20)="Monthly") ), IF(AND(I20=4%,J20=0%,K20=0%,L20=0%),1%, IF(AND(I20=4%,J20=2.5%,K20=0%,L20=10%),2%, IF(AND(I20=4%,J20=0%,K20=7%,L20=10%),3%,0%))), IF( OR( AND(TRIM(D20)="P1Y",TRIM(E20)="Annual"), AND(TRIM(D20)="P3Y",TRIM(E20)="Annual"), AND(TRIM(D20)="P3Y",TRIM(E20)="Triennial") ), IF(AND(I20=4%,J20=0%,K20=0%,L20=0%),3%, IF(AND(I20=4%,J20=2.5%,K20=0%,L20=10%),10%, IF(AND(I20=4%,J20=0%,K20=7%,L20=10%),14%,0%))), 0% )))) -> 0.01 | N20: =H20-(H20*M20) -> 427.68
A21: CFQ7TTC0HDK0 | B21: 000D | C21: Advanced Communications (Education Student Pricing) | D21: P1M | E21: Monthly | F21: Education | G21: 180 | H21: 144 | I21: =IF(COUNTIFS(Addendum!C:C,A21,Addendum!D:D,IF(ISNUMBER(B21),TEXT(B21,"0000"),B21),Addendum!E:E,"X")>0,4%,0) -> 0.04 | J21: =IF(COUNTIFS(Addendum!C:C,A21,Addendum!D:D,IF(ISNUMBER(B21),TEXT(B21,"0000"),B21),Addendum!F:F,"X")>0,2.5%,0) -> 0 | K21: =IF(COUNTIFS(Addendum!C:C,A21,Addendum!D:D,IF(ISNUMBER(B21),TEXT(B21,"0000"),B21),Addendum!G:G,"X")>0,7%,0) -> 0 | L21: =IF(COUNTIFS(Addendum!C:C,A21,Addendum!D:D,IF(ISNUMBER(B21),TEXT(B21,"0000"),B21),Addendum!I:I,"X")>0,10%,0) -> 0 | M21: =IF(AND(I21=0%,J21=0%,K21=0%,L21=0%),0%, IF(OR(TRIM(E21)="OneTime",TRIM(D21)=""),0%, IF( OR( TRIM(D21)="P1M", AND(TRIM(D21)="P1Y",TRIM(E21)="Monthly"), AND(TRIM(D21)="P3Y",TRIM(E21)="Monthly") ), IF(AND(I21=4%,J21=0%,K21=0%,L21=0%),1%, IF(AND(I21=4%,J21=2.5%,K21=0%,L21=10%),2%, IF(AND(I21=4%,J21=0%,K21=7%,L21=10%),3%,0%))), IF( OR( AND(TRIM(D21)="P1Y",TRIM(E21)="Annual"), AND(TRIM(D21)="P3Y",TRIM(E21)="Annual"), AND(TRIM(D21)="P3Y",TRIM(E21)="Triennial") ), IF(AND(I21=4%,J21=0%,K21=0%,L21=0%),3%, IF(AND(I21=4%,J21=2.5%,K21=0%,L21=10%),10%, IF(AND(I21=4%,J21=0%,K21=7%,L21=10%),14%,0%))), 0% )))) -> 0.01 | N21: =H21-(H21*M21) -> 142.56
A22: CFQ7TTC0HDK0 | B22: 1 | C22: Advanced Communications | D22: P1M | E22: Monthly | F22: Commercial | G22: 1200 | H22: 960 | I22: =IF(COUNTIFS(Addendum!C:C,A22,Addendum!D:D,IF(ISNUMBER(B22),TEXT(B22,"0000"),B22),Addendum!E:E,"X")>0,4%,0) -> 0.04 | J22: =IF(COUNTIFS(Addendum!C:C,A22,Addendum!D:D,IF(ISNUMBER(B22),TEXT(B22,"0000"),B22),Addendum!F:F,"X")>0,2.5%,0) -> 0 | K22: =IF(COUNTIFS(Addendum!C:C,A22,Addendum!D:D,IF(ISNUMBER(B22),TEXT(B22,"0000"),B22),Addendum!G:G,"X")>0,7%,0) -> 0 | L22: =IF(COUNTIFS(Addendum!C:C,A22,Addendum!D:D,IF(ISNUMBER(B22),TEXT(B22,"0000"),B22),Addendum!I:I,"X")>0,10%,0) -> 0 | M22: =IF(AND(I22=0%,J22=0%,K22=0%,L22=0%),0%, IF(OR(TRIM(E22)="OneTime",TRIM(D22)=""),0%, IF( OR( TRIM(D22)="P1M", AND(TRIM(D22)="P1Y",TRIM(E22)="Monthly"), AND(TRIM(D22)="P3Y",TRIM(E22)="Monthly") ), IF(AND(I22=4%,J22=0%,K22=0%,L22=0%),1%, IF(AND(I22=4%,J22=2.5%,K22=0%,L22=10%),2%, IF(AND(I22=4%,J22=0%,K22=7%,L22=10%),3%,0%))), IF( OR( AND(TRIM(D22)="P1Y",TRIM(E22)="Annual"), AND(TRIM(D22)="P3Y",TRIM(E22)="Annual"), AND(TRIM(D22)="P3Y",TRIM(E22)="Triennial") ), IF(AND(I22=4%,J22=0%,K22=0%,L22=0%),3%, IF(AND(I22=4%,J22=2.5%,K22=0%,L22=10%),10%, IF(AND(I22=4%,J22=0%,K22=7%,L22=10%),14%,0%))), 0% )))) -> 0.01 | N22: =H22-(H22*M22) -> 950.4
A23: CFQ7TTC0HDK0 | B23: 000B | C23: Advanced Communications (Non-Profit Pricing) | D23: P1Y | E23: Annual | F23: Charity | G23: 4800 | H23: 4320 | I23: =IF(COUNTIFS(Addendum!C:C,A23,Addendum!D:D,IF(ISNUMBER(B23),TEXT(B23,"0000"),B23),Addendum!E:E,"X")>0,4%,0) -> 0.04 | J23: =IF(COUNTIFS(Addendum!C:C,A23,Addendum!D:D,IF(ISNUMBER(B23),TEXT(B23,"0000"),B23),Addendum!F:F,"X")>0,2.5%,0) -> 0 | K23: =IF(COUNTIFS(Addendum!C:C,A23,Addendum!D:D,IF(ISNUMBER(B23),TEXT(B23,"0000"),B23),Addendum!G:G,"X")>0,7%,0) -> 0 | L23: =IF(COUNTIFS(Addendum!C:C,A23,Addendum!D:D,IF(ISNUMBER(B23),TEXT(B23,"0000"),B23),Addendum!I:I,"X")>0,10%,0) -> 0 | M23: =IF(AND(I23=0%,J23=0%,K23=0%,L23=0%),0%, IF(OR(TRIM(E23)="OneTime",TRIM(D23)=""),0%, IF( OR( TRIM(D23)="P1M", AND(TRIM(D23)="P1Y",TRIM(E23)="Monthly"), AND(TRIM(D23)="P3Y",TRIM(E23)="Monthly") ), IF(AND(I23=4%,J23=0%,K23=0%,L23=0%),1%, IF(AND(I23=4%,J23=2.5%,K23=0%,L23=10%),2%, IF(AND(I23=4%,J23=0%,K23=7%,L23=10%),3%,0%))), IF( OR( AND(TRIM(D23)="P1Y",TRIM(E23)="Annual"), AND(TRIM(D23)="P3Y",TRIM(E23)="Annual"), AND(TRIM(D23)="P3Y",TRIM(E23)="Triennial") ), IF(AND(I23=4%,J23=0%,K23=0%,L23=0%),3%, IF(AND(I23=4%,J23=2.5%,K23=0%,L23=10%),10%, IF(AND(I23=4%,J23=0%,K23=7%,L23=10%),14%,0%))), 0% )))) -> 0.03 | N23: =H23-(H23*M23) -> 4190.4
A24: CFQ7TTC0HDK0 | B24: 1 | C24: Advanced Communications | D24: P1Y | E24: Annual | F24: Commercial | G24: 12000 | H24: 9600 | I24: =IF(COUNTIFS(Addendum!C:C,A24,Addendum!D:D,IF(ISNUMBER(B24),TEXT(B24,"0000"),B24),Addendum!E:E,"X")>0,4%,0) -> 0.04 | J24: =IF(COUNTIFS(Addendum!C:C,A24,Addendum!D:D,IF(ISNUMBER(B24),TEXT(B24,"0000"),B24),Addendum!F:F,"X")>0,2.5%,0) -> 0 | K24: =IF(COUNTIFS(Addendum!C:C,A24,Addendum!D:D,IF(ISNUMBER(B24),TEXT(B24,"0000"),B24),Addendum!G:G,"X")>0,7%,0) -> 0 | L24: =IF(COUNTIFS(Addendum!C:C,A24,Addendum!D:D,IF(ISNUMBER(B24),TEXT(B24,"0000"),B24),Addendum!I:I,"X")>0,10%,0) -> 0 | M24: =IF(AND(I24=0%,J24=0%,K24=0%,L24=0%),0%, IF(OR(TRIM(E24)="OneTime",TRIM(D24)=""),0%, IF( OR( TRIM(D24)="P1M", AND(TRIM(D24)="P1Y",TRIM(E24)="Monthly"), AND(TRIM(D24)="P3Y",TRIM(E24)="Monthly") ), IF(AND(I24=4%,J24=0%,K24=0%,L24=0%),1%, IF(AND(I24=4%,J24=2.5%,K24=0%,L24=10%),2%, IF(AND(I24=4%,J24=0%,K24=7%,L24=10%),3%,0%))), IF( OR( AND(TRIM(D24)="P1Y",TRIM(E24)="Annual"), AND(TRIM(D24)="P3Y",TRIM(E24)="Annual"), AND(TRIM(D24)="P3Y",TRIM(E24)="Triennial") ), IF(AND(I24=4%,J24=0%,K24=0%,L24=0%),3%, IF(AND(I24=4%,J24=2.5%,K24=0%,L24=10%),10%, IF(AND(I24=4%,J24=0%,K24=7%,L24=10%),14%,0%))), 0% )))) -> 0.03 | N24: =H24-(H24*M24) -> 9312
A25: CFQ7TTC0HDK0 | B25: 1 | C25: Advanced Communications | D25: P1Y | E25: Monthly | F25: Commercial | G25: 12600 | H25: 10080 | I25: =IF(COUNTIFS(Addendum!C:C,A25,Addendum!D:D,IF(ISNUMBER(B25),TEXT(B25,"0000"),B25),Addendum!E:E,"X")>0,4%,0) -> 0.04 | J25: =IF(COUNTIFS(Addendum!C:C,A25,Addendum!D:D,IF(ISNUMBER(B25),TEXT(B25,"0000"),B25),Addendum!F:F,"X")>0,2.5%,0) -> 0 | K25: =IF(COUNTIFS(Addendum!C:C,A25,Addendum!D:D,IF(ISNUMBER(B25),TEXT(B25,"0000"),B25),Addendum!G:G,"X")>0,7%,0) -> 0 | L25: =IF(COUNTIFS(Addendum!C:C,A25,Addendum!D:D,IF(ISNUMBER(B25),TEXT(B25,"0000"),B25),Addendum!I:I,"X")>0,10%,0) -> 0 | M25: =IF(AND(I25=0%,J25=0%,K25=0%,L25=0%),0%, IF(OR(TRIM(E25)="OneTime",TRIM(D25)=""),0%, IF( OR( TRIM(D25)="P1M", AND(TRIM(D25)="P1Y",TRIM(E25)="Monthly"), AND(TRIM(D25)="P3Y",TRIM(E25)="Monthly") ), IF(AND(I25=4%,J25=0%,K25=0%,L25=0%),1%, IF(AND(I25=4%,J25=2.5%,K25=0%,L25=10%),2%, IF(AND(I25=4%,J25=0%,K25=7%,L25=10%),3%,0%))), IF( OR( AND(TRIM(D25)="P1Y",TRIM(E25)="Annual"), AND(TRIM(D25)="P3Y",TRIM(E25)="Annual"), AND(TRIM(D25)="P3Y",TRIM(E25)="Triennial") ), IF(AND(I25=4%,J25=0%,K25=0%,L25=0%),3%, IF(AND(I25=4%,J25=2.5%,K25=0%,L25=10%),10%, IF(AND(I25=4%,J25=0%,K25=7%,L25=10%),14%,0%))), 0% )))) -> 0.01 | N25: =H25-(H25*M25) -> 9979.2
A26: CFQ7TTC0HDK0 | B26: 000D | C26: Advanced Communications (Education Student Pricing) | D26: P1Y | E26: Annual | F26: Education | G26: 1800 | H26: 1440 | I26: =IF(COUNTIFS(Addendum!C:C,A26,Addendum!D:D,IF(ISNUMBER(B26),TEXT(B26,"0000"),B26),Addendum!E:E,"X")>0,4%,0) -> 0.04 | J26: =IF(COUNTIFS(Addendum!C:C,A26,Addendum!D:D,IF(ISNUMBER(B26),TEXT(B26,"0000"),B26),Addendum!F:F,"X")>0,2.5%,0) -> 0 | K26: =IF(COUNTIFS(Addendum!C:C,A26,Addendum!D:D,IF(ISNUMBER(B26),TEXT(B26,"0000"),B26),Addendum!G:G,"X")>0,7%,0) -> 0 | L26: =IF(COUNTIFS(Addendum!C:C,A26,Addendum!D:D,IF(ISNUMBER(B26),TEXT(B26,"0000"),B26),Addendum!I:I,"X")>0,10%,0) -> 0 | M26: =IF(AND(I26=0%,J26=0%,K26=0%,L26=0%),0%, IF(OR(TRIM(E26)="OneTime",TRIM(D26)=""),0%, IF( OR( TRIM(D26)="P1M", AND(TRIM(D26)="P1Y",TRIM(E26)="Monthly"), AND(TRIM(D26)="P3Y",TRIM(E26)="Monthly") ), IF(AND(I26=4%,J26=0%,K26=0%,L26=0%),1%, IF(AND(I26=4%,J26=2.5%,K26=0%,L26=10%),2%, IF(AND(I26=4%,J26=0%,K26=7%,L26=10%),3%,0%))), IF( OR( AND(TRIM(D26)="P1Y",TRIM(E26)="Annual"), AND(TRIM(D26)="P3Y",TRIM(E26)="Annual"), AND(TRIM(D26)="P3Y",TRIM(E26)="Triennial") ), IF(AND(I26=4%,J26=0%,K26=0%,L26=0%),3%, IF(AND(I26=4%,J26=2.5%,K26=0%,L26=10%),10%, IF(AND(I26=4%,J26=0%,K26=7%,L26=10%),14%,0%))), 0% )))) -> 0.03 | N26: =H26-(H26*M26) -> 1396.8
A27: CFQ7TTC0HDK0 | B27: 000C | C27: Advanced Communications (Education Faculty Pricing) | D27: P1M | E27: Monthly | F27: Education | G27: 240 | H27: 192 | I27: =IF(COUNTIFS(Addendum!C:C,A27,Addendum!D:D,IF(ISNUMBER(B27),TEXT(B27,"0000"),B27),Addendum!E:E,"X")>0,4%,0) -> 0.04 | J27: =IF(COUNTIFS(Addendum!C:C,A27,Addendum!D:D,IF(ISNUMBER(B27),TEXT(B27,"0000"),B27),Addendum!F:F,"X")>0,2.5%,0) -> 0 | K27: =IF(COUNTIFS(Addendum!C:C,A27,Addendum!D:D,IF(ISNUMBER(B27),TEXT(B27,"0000"),B27),Addendum!G:G,"X")>0,7%,0) -> 0 | L27: =IF(COUNTIFS(Addendum!C:C,A27,Addendum!D:D,IF(ISNUMBER(B27),TEXT(B27,"0000"),B27),Addendum!I:I,"X")>0,10%,0) -> 0 | M27: =IF(AND(I27=0%,J27=0%,K27=0%,L27=0%),0%, IF(OR(TRIM(E27)="OneTime",TRIM(D27)=""),0%, IF( OR( TRIM(D27)="P1M", AND(TRIM(D27)="P1Y",TRIM(E27)="Monthly"), AND(TRIM(D27)="P3Y",TRIM(E27)="Monthly") ), IF(AND(I27=4%,J27=0%,K27=0%,L27=0%),1%, IF(AND(I27=4%,J27=2.5%,K27=0%,L27=10%),2%, IF(AND(I27=4%,J27=0%,K27=7%,L27=10%),3%,0%))), IF( OR( AND(TRIM(D27)="P1Y",TRIM(E27)="Annual"), AND(TRIM(D27)="P3Y",TRIM(E27)="Annual"), AND(TRIM(D27)="P3Y",TRIM(E27)="Triennial") ), IF(AND(I27=4%,J27=0%,K27=0%,L27=0%),3%, IF(AND(I27=4%,J27=2.5%,K27=0%,L27=10%),10%, IF(AND(I27=4%,J27=0%,K27=7%,L27=10%),14%,0%))), 0% )))) -> 0.01 | N27: =H27-(H27*M27) -> 190.08
A28: CFQ7TTC0LHQD | B28: 4 | C28: Advanced eDiscovery Storage (Education Faculty Pricing) | D28: P1M | E28: Monthly | F28: Education | G28: 1998 | H28: 1598.4 | I28: =IF(COUNTIFS(Addendum!C:C,A28,Addendum!D:D,IF(ISNUMBER(B28),TEXT(B28,"0000"),B28),Addendum!E:E,"X")>0,4%,0) -> 0 | J28: =IF(COUNTIFS(Addendum!C:C,A28,Addendum!D:D,IF(ISNUMBER(B28),TEXT(B28,"0000"),B28),Addendum!F:F,"X")>0,2.5%,0) -> 0 | K28: =IF(COUNTIFS(Addendum!C:C,A28,Addendum!D:D,IF(ISNUMBER(B28),TEXT(B28,"0000"),B28),Addendum!G:G,"X")>0,7%,0) -> 0 | L28: =IF(COUNTIFS(Addendum!C:C,A28,Addendum!D:D,IF(ISNUMBER(B28),TEXT(B28,"0000"),B28),Addendum!I:I,"X")>0,10%,0) -> 0 | M28: =IF(AND(I28=0%,J28=0%,K28=0%,L28=0%),0%, IF(OR(TRIM(E28)="OneTime",TRIM(D28)=""),0%, IF( OR( TRIM(D28)="P1M", AND(TRIM(D28)="P1Y",TRIM(E28)="Monthly"), AND(TRIM(D28)="P3Y",TRIM(E28)="Monthly") ), IF(AND(I28=4%,J28=0%,K28=0%,L28=0%),1%, IF(AND(I28=4%,J28=2.5%,K28=0%,L28=10%),2%, IF(AND(I28=4%,J28=0%,K28=7%,L28=10%),3%,0%))), IF( OR( AND(TRIM(D28)="P1Y",TRIM(E28)="Annual"), AND(TRIM(D28)="P3Y",TRIM(E28)="Annual"), AND(TRIM(D28)="P3Y",TRIM(E28)="Triennial") ), IF(AND(I28=4%,J28=0%,K28=0%,L28=0%),3%, IF(AND(I28=4%,J28=2.5%,K28=0%,L28=10%),10%, IF(AND(I28=4%,J28=0%,K28=7%,L28=10%),14%,0%))), 0% )))) -> 0 | N28: =H28-(H28*M28) -> 1598.4
A29: CFQ7TTC0LHQD | B29: 4 | C29: Advanced eDiscovery Storage (Education Faculty Pricing) | D29: P1Y | E29: Monthly | F29: Education | G29: 20979 | H29: 16783.2 | I29: =IF(COUNTIFS(Addendum!C:C,A29,Addendum!D:D,IF(ISNUMBER(B29),TEXT(B29,"0000"),B29),Addendum!E:E,"X")>0,4%,0) -> 0 | J29: =IF(COUNTIFS(Addendum!C:C,A29,Addendum!D:D,IF(ISNUMBER(B29),TEXT(B29,"0000"),B29),Addendum!F:F,"X")>0,2.5%,0) -> 0 | K29: =IF(COUNTIFS(Addendum!C:C,A29,Addendum!D:D,IF(ISNUMBER(B29),TEXT(B29,"0000"),B29),Addendum!G:G,"X")>0,7%,0) -> 0 | L29: =IF(COUNTIFS(Addendum!C:C,A29,Addendum!D:D,IF(ISNUMBER(B29),TEXT(B29,"0000"),B29),Addendum!I:I,"X")>0,10%,0) -> 0 | M29: =IF(AND(I29=0%,J29=0%,K29=0%,L29=0%),0%, IF(OR(TRIM(E29)="OneTime",TRIM(D29)=""),0%, IF( OR( TRIM(D29)="P1M", AND(TRIM(D29)="P1Y",TRIM(E29)="Monthly"), AND(TRIM(D29)="P3Y",TRIM(E29)="Monthly") ), IF(AND(I29=4%,J29=0%,K29=0%,L29=0%),1%, IF(AND(I29=4%,J29=2.5%,K29=0%,L29=10%),2%, IF(AND(I29=4%,J29=0%,K29=7%,L29=10%),3%,0%))), IF( OR( AND(TRIM(D29)="P1Y",TRIM(E29)="Annual"), AND(TRIM(D29)="P3Y",TRIM(E29)="Annual"), AND(TRIM(D29)="P3Y",TRIM(E29)="Triennial") ), IF(AND(I29=4%,J29=0%,K29=0%,L29=0%),3%, IF(AND(I29=4%,J29=2.5%,K29=0%,L29=10%),10%, IF(AND(I29=4%,J29=0%,K29=7%,L29=10%),14%,0%))), 0% )))) -> 0 | N29: =H29-(H29*M29) -> 16783.2
A30: CFQ7TTC0LHQD | B30: 4 | C30: Advanced eDiscovery Storage (Education Faculty Pricing) | D30: P1Y | E30: Annual | F30: Education | G30: 19980 | H30: 15984 | I30: =IF(COUNTIFS(Addendum!C:C,A30,Addendum!D:D,IF(ISNUMBER(B30),TEXT(B30,"0000"),B30),Addendum!E:E,"X")>0,4%,0) -> 0 | J30: =IF(COUNTIFS(Addendum!C:C,A30,Addendum!D:D,IF(ISNUMBER(B30),TEXT(B30,"0000"),B30),Addendum!F:F,"X")>0,2.5%,0) -> 0 | K30: =IF(COUNTIFS(Addendum!C:C,A30,Addendum!D:D,IF(ISNUMBER(B30),TEXT(B30,"0000"),B30),Addendum!G:G,"X")>0,7%,0) -> 0 | L30: =IF(COUNTIFS(Addendum!C:C,A30,Addendum!D:D,IF(ISNUMBER(B30),TEXT(B30,"0000"),B30),Addendum!I:I,"X")>0,10%,0) -> 0 | M30: =IF(AND(I30=0%,J30=0%,K30=0%,L30=0%),0%, IF(OR(TRIM(E30)="OneTime",TRIM(D30)=""),0%, IF( OR( TRIM(D30)="P1M", AND(TRIM(D30)="P1Y",TRIM(E30)="Monthly"), AND(TRIM(D30)="P3Y",TRIM(E30)="Monthly") ), IF(AND(I30=4%,J30=0%,K30=0%,L30=0%),1%, IF(AND(I30=4%,J30=2.5%,K30=0%,L30=10%),2%, IF(AND(I30=4%,J30=0%,K30=7%,L30=10%),3%,0%))), IF( OR( AND(TRIM(D30)="P1Y",TRIM(E30)="Annual"), AND(TRIM(D30)="P3Y",TRIM(E30)="Annual"), AND(TRIM(D30)="P3Y",TRIM(E30)="Triennial") ), IF(AND(I30=4%,J30=0%,K30=0%,L30=0%),3%, IF(AND(I30=4%,J30=2.5%,K30=0%,L30=10%),10%, IF(AND(I30=4%,J30=0%,K30=7%,L30=10%),14%,0%))), 0% )))) -> 0 | N30: =H30-(H30*M30) -> 15984
A31: CFQ7TTC0LHQD | B31: 1 | C31: Advanced eDiscovery Storage | D31: P1Y | E31: Monthly | F31: Commercial | G31: 104832 | H31: 83865.6 | I31: =IF(COUNTIFS(Addendum!C:C,A31,Addendum!D:D,IF(ISNUMBER(B31),TEXT(B31,"0000"),B31),Addendum!E:E,"X")>0,4%,0) -> 0 | J31: =IF(COUNTIFS(Addendum!C:C,A31,Addendum!D:D,IF(ISNUMBER(B31),TEXT(B31,"0000"),B31),Addendum!F:F,"X")>0,2.5%,0) -> 0 | K31: =IF(COUNTIFS(Addendum!C:C,A31,Addendum!D:D,IF(ISNUMBER(B31),TEXT(B31,"0000"),B31),Addendum!G:G,"X")>0,7%,0) -> 0 | L31: =IF(COUNTIFS(Addendum!C:C,A31,Addendum!D:D,IF(ISNUMBER(B31),TEXT(B31,"0000"),B31),Addendum!I:I,"X")>0,10%,0) -> 0 | M31: =IF(AND(I31=0%,J31=0%,K31=0%,L31=0%),0%, IF(OR(TRIM(E31)="OneTime",TRIM(D31)=""),0%, IF( OR( TRIM(D31)="P1M", AND(TRIM(D31)="P1Y",TRIM(E31)="Monthly"), AND(TRIM(D31)="P3Y",TRIM(E31)="Monthly") ), IF(AND(I31=4%,J31=0%,K31=0%,L31=0%),1%, IF(AND(I31=4%,J31=2.5%,K31=0%,L31=10%),2%, IF(AND(I31=4%,J31=0%,K31=7%,L31=10%),3%,0%))), IF( OR( AND(TRIM(D31)="P1Y",TRIM(E31)="Annual"), AND(TRIM(D31)="P3Y",TRIM(E31)="Annual"), AND(TRIM(D31)="P3Y",TRIM(E31)="Triennial") ), IF(AND(I31=4%,J31=0%,K31=0%,L31=0%),3%, IF(AND(I31=4%,J31=2.5%,K31=0%,L31=10%),10%, IF(AND(I31=4%,J31=0%,K31=7%,L31=10%),14%,0%))), 0% )))) -> 0 | N31: =H31-(H31*M31) -> 83865.6
A32: CFQ7TTC0LHQD | B32: 5 | C32: Advanced eDiscovery Storage (Non-Profit Pricing) | D32: P1Y | E32: Monthly | F32: Charity | G32: 41958 | H32: 37762.2 | I32: =IF(COUNTIFS(Addendum!C:C,A32,Addendum!D:D,IF(ISNUMBER(B32),TEXT(B32,"0000"),B32),Addendum!E:E,"X")>0,4%,0) -> 0 | J32: =IF(COUNTIFS(Addendum!C:C,A32,Addendum!D:D,IF(ISNUMBER(B32),TEXT(B32,"0000"),B32),Addendum!F:F,"X")>0,2.5%,0) -> 0 | K32: =IF(COUNTIFS(Addendum!C:C,A32,Addendum!D:D,IF(ISNUMBER(B32),TEXT(B32,"0000"),B32),Addendum!G:G,"X")>0,7%,0) -> 0 | L32: =IF(COUNTIFS(Addendum!C:C,A32,Addendum!D:D,IF(ISNUMBER(B32),TEXT(B32,"0000"),B32),Addendum!I:I,"X")>0,10%,0) -> 0 | M32: =IF(AND(I32=0%,J32=0%,K32=0%,L32=0%),0%, IF(OR(TRIM(E32)="OneTime",TRIM(D32)=""),0%, IF( OR( TRIM(D32)="P1M", AND(TRIM(D32)="P1Y",TRIM(E32)="Monthly"), AND(TRIM(D32)="P3Y",TRIM(E32)="Monthly") ), IF(AND(I32=4%,J32=0%,K32=0%,L32=0%),1%, IF(AND(I32=4%,J32=2.5%,K32=0%,L32=10%),2%, IF(AND(I32=4%,J32=0%,K32=7%,L32=10%),3%,0%))), IF( OR( AND(TRIM(D32)="P1Y",TRIM(E32)="Annual"), AND(TRIM(D32)="P3Y",TRIM(E32)="Annual"), AND(TRIM(D32)="P3Y",TRIM(E32)="Triennial") ), IF(AND(I32=4%,J32=0%,K32=0%,L32=0%),3%, IF(AND(I32=4%,J32=2.5%,K32=0%,L32=10%),10%, IF(AND(I32=4%,J32=0%,K32=7%,L32=10%),14%,0%))), 0% )))) -> 0 | N32: =H32-(H32*M32) -> 37762.2
A33: CFQ7TTC0LHQD | B33: 1 | C33: Advanced eDiscovery Storage | D33: P1Y | E33: Annual | F33: Commercial | G33: 99840 | H33: 79872 | I33: =IF(COUNTIFS(Addendum!C:C,A33,Addendum!D:D,IF(ISNUMBER(B33),TEXT(B33,"0000"),B33),Addendum!E:E,"X")>0,4%,0) -> 0 | J33: =IF(COUNTIFS(Addendum!C:C,A33,Addendum!D:D,IF(ISNUMBER(B33),TEXT(B33,"0000"),B33),Addendum!F:F,"X")>0,2.5%,0) -> 0 | K33: =IF(COUNTIFS(Addendum!C:C,A33,Addendum!D:D,IF(ISNUMBER(B33),TEXT(B33,"0000"),B33),Addendum!G:G,"X")>0,7%,0) -> 0 | L33: =IF(COUNTIFS(Addendum!C:C,A33,Addendum!D:D,IF(ISNUMBER(B33),TEXT(B33,"0000"),B33),Addendum!I:I,"X")>0,10%,0) -> 0 | M33: =IF(AND(I33=0%,J33=0%,K33=0%,L33=0%),0%, IF(OR(TRIM(E33)="OneTime",TRIM(D33)=""),0%, IF( OR( TRIM(D33)="P1M", AND(TRIM(D33)="P1Y",TRIM(E33)="Monthly"), AND(TRIM(D33)="P3Y",TRIM(E33)="Monthly") ), IF(AND(I33=4%,J33=0%,K33=0%,L33=0%),1%, IF(AND(I33=4%,J33=2.5%,K33=0%,L33=10%),2%, IF(AND(I33=4%,J33=0%,K33=7%,L33=10%),3%,0%))), IF( OR( AND(TRIM(D33)="P1Y",TRIM(E33)="Annual"), AND(TRIM(D33)="P3Y",TRIM(E33)="Annual"), AND(TRIM(D33)="P3Y",TRIM(E33)="Triennial") ), IF(AND(I33=4%,J33=0%,K33=0%,L33=0%),3%, IF(AND(I33=4%,J33=2.5%,K33=0%,L33=10%),10%, IF(AND(I33=4%,J33=0%,K33=7%,L33=10%),14%,0%))), 0% )))) -> 0 | N33: =H33-(H33*M33) -> 79872
A34: CFQ7TTC0LHQD | B34: 5 | C34: Advanced eDiscovery Storage (Non-Profit Pricing) | D34: P1M | E34: Monthly | F34: Charity | G34: 3996 | H34: 3596.4 | I34: =IF(COUNTIFS(Addendum!C:C,A34,Addendum!D:D,IF(ISNUMBER(B34),TEXT(B34,"0000"),B34),Addendum!E:E,"X")>0,4%,0) -> 0 | J34: =IF(COUNTIFS(Addendum!C:C,A34,Addendum!D:D,IF(ISNUMBER(B34),TEXT(B34,"0000"),B34),Addendum!F:F,"X")>0,2.5%,0) -> 0 | K34: =IF(COUNTIFS(Addendum!C:C,A34,Addendum!D:D,IF(ISNUMBER(B34),TEXT(B34,"0000"),B34),Addendum!G:G,"X")>0,7%,0) -> 0 | L34: =IF(COUNTIFS(Addendum!C:C,A34,Addendum!D:D,IF(ISNUMBER(B34),TEXT(B34,"0000"),B34),Addendum!I:I,"X")>0,10%,0) -> 0 | M34: =IF(AND(I34=0%,J34=0%,K34=0%,L34=0%),0%, IF(OR(TRIM(E34)="OneTime",TRIM(D34)=""),0%, IF( OR( TRIM(D34)="P1M", AND(TRIM(D34)="P1Y",TRIM(E34)="Monthly"), AND(TRIM(D34)="P3Y",TRIM(E34)="Monthly") ), IF(AND(I34=4%,J34=0%,K34=0%,L34=0%),1%, IF(AND(I34=4%,J34=2.5%,K34=0%,L34=10%),2%, IF(AND(I34=4%,J34=0%,K34=7%,L34=10%),3%,0%))), IF( OR( AND(TRIM(D34)="P1Y",TRIM(E34)="Annual"), AND(TRIM(D34)="P3Y",TRIM(E34)="Annual"), AND(TRIM(D34)="P3Y",TRIM(E34)="Triennial") ), IF(AND(I34=4%,J34=0%,K34=0%,L34=0%),3%, IF(AND(I34=4%,J34=2.5%,K34=0%,L34=10%),10%, IF(AND(I34=4%,J34=0%,K34=7%,L34=10%),14%,0%))), 0% )))) -> 0 | N34: =H34-(H34*M34) -> 3596.4
A35: CFQ7TTC0LHQD | B35: 5 | C35: Advanced eDiscovery Storage (Non-Profit Pricing) | D35: P1Y | E35: Annual | F35: Charity | G35: 39960 | H35: 35964 | I35: =IF(COUNTIFS(Addendum!C:C,A35,Addendum!D:D,IF(ISNUMBER(B35),TEXT(B35,"0000"),B35),Addendum!E:E,"X")>0,4%,0) -> 0 | J35: =IF(COUNTIFS(Addendum!C:C,A35,Addendum!D:D,IF(ISNUMBER(B35),TEXT(B35,"0000"),B35),Addendum!F:F,"X")>0,2.5%,0) -> 0 | K35: =IF(COUNTIFS(Addendum!C:C,A35,Addendum!D:D,IF(ISNUMBER(B35),TEXT(B35,"0000"),B35),Addendum!G:G,"X")>0,7%,0) -> 0 | L35: =IF(COUNTIFS(Addendum!C:C,A35,Addendum!D:D,IF(ISNUMBER(B35),TEXT(B35,"0000"),B35),Addendum!I:I,"X")>0,10%,0) -> 0 | M35: =IF(AND(I35=0%,J35=0%,K35=0%,L35=0%),0%, IF(OR(TRIM(E35)="OneTime",TRIM(D35)=""),0%, IF( OR( TRIM(D35)="P1M", AND(TRIM(D35)="P1Y",TRIM(E35)="Monthly"), AND(TRIM(D35)="P3Y",TRIM(E35)="Monthly") ), IF(AND(I35=4%,J35=0%,K35=0%,L35=0%),1%, IF(AND(I35=4%,J35=2.5%,K35=0%,L35=10%),2%, IF(AND(I35=4%,J35=0%,K35=7%,L35=10%),3%,0%))), IF( OR( AND(TRIM(D35)="P1Y",TRIM(E35)="Annual"), AND(TRIM(D35)="P3Y",TRIM(E35)="Annual"), AND(TRIM(D35)="P3Y",TRIM(E35)="Triennial") ), IF(AND(I35=4%,J35=0%,K35=0%,L35=0%),3%, IF(AND(I35=4%,J35=2.5%,K35=0%,L35=10%),10%, IF(AND(I35=4%,J35=0%,K35=7%,L35=10%),14%,0%))), 0% )))) -> 0 | N35: =H35-(H35*M35) -> 35964
A36: CFQ7TTC0LHQD | B36: 1 | C36: Advanced eDiscovery Storage | D36: P1M | E36: Monthly | F36: Commercial | G36: 9984 | H36: 7987.2 | I36: =IF(COUNTIFS(Addendum!C:C,A36,Addendum!D:D,IF(ISNUMBER(B36),TEXT(B36,"0000"),B36),Addendum!E:E,"X")>0,4%,0) -> 0 | J36: =IF(COUNTIFS(Addendum!C:C,A36,Addendum!D:D,IF(ISNUMBER(B36),TEXT(B36,"0000"),B36),Addendum!F:F,"X")>0,2.5%,0) -> 0 | K36: =IF(COUNTIFS(Addendum!C:C,A36,Addendum!D:D,IF(ISNUMBER(B36),TEXT(B36,"0000"),B36),Addendum!G:G,"X")>0,7%,0) -> 0 | L36: =IF(COUNTIFS(Addendum!C:C,A36,Addendum!D:D,IF(ISNUMBER(B36),TEXT(B36,"0000"),B36),Addendum!I:I,"X")>0,10%,0) -> 0 | M36: =IF(AND(I36=0%,J36=0%,K36=0%,L36=0%),0%, IF(OR(TRIM(E36)="OneTime",TRIM(D36)=""),0%, IF( OR( TRIM(D36)="P1M", AND(TRIM(D36)="P1Y",TRIM(E36)="Monthly"), AND(TRIM(D36)="P3Y",TRIM(E36)="Monthly") ), IF(AND(I36=4%,J36=0%,K36=0%,L36=0%),1%, IF(AND(I36=4%,J36=2.5%,K36=0%,L36=10%),2%, IF(AND(I36=4%,J36=0%,K36=7%,L36=10%),3%,0%))), IF( OR( AND(TRIM(D36)="P1Y",TRIM(E36)="Annual"), AND(TRIM(D36)="P3Y",TRIM(E36)="Annual"), AND(TRIM(D36)="P3Y",TRIM(E36)="Triennial") ), IF(AND(I36=4%,J36=0%,K36=0%,L36=0%),3%, IF(AND(I36=4%,J36=2.5%,K36=0%,L36=10%),10%, IF(AND(I36=4%,J36=0%,K36=7%,L36=10%),14%,0%))), 0% )))) -> 0 | N36: =H36-(H36*M36) -> 7987.2
A37: CFQ7TTC10RSN | B37: 3 | C37: Microsoft Defender and Purview Suites for Microsoft 365 Business Premium | D37: P1Y | E37: Monthly | F37: Commercial | G37: 15750 | H37: 12600 | I37: =IF(COUNTIFS(Addendum!C:C,A37,Addendum!D:D,IF(ISNUMBER(B37),TEXT(B37,"0000"),B37),Addendum!E:E,"X")>0,4%,0) -> 0.04 | J37: =IF(COUNTIFS(Addendum!C:C,A37,Addendum!D:D,IF(ISNUMBER(B37),TEXT(B37,"0000"),B37),Addendum!F:F,"X")>0,2.5%,0) -> 0.025 | K37: =IF(COUNTIFS(Addendum!C:C,A37,Addendum!D:D,IF(ISNUMBER(B37),TEXT(B37,"0000"),B37),Addendum!G:G,"X")>0,7%,0) -> 0 | L37: =IF(COUNTIFS(Addendum!C:C,A37,Addendum!D:D,IF(ISNUMBER(B37),TEXT(B37,"0000"),B37),Addendum!I:I,"X")>0,10%,0) -> 0.1 | M37: =IF(AND(I37=0%,J37=0%,K37=0%,L37=0%),0%, IF(OR(TRIM(E37)="OneTime",TRIM(D37)=""),0%, IF( OR( TRIM(D37)="P1M", AND(TRIM(D37)="P1Y",TRIM(E37)="Monthly"), AND(TRIM(D37)="P3Y",TRIM(E37)="Monthly") ), IF(AND(I37=4%,J37=0%,K37=0%,L37=0%),1%, IF(AND(I37=4%,J37=2.5%,K37=0%,L37=10%),2%, IF(AND(I37=4%,J37=0%,K37=7%,L37=10%),3%,0%))), IF( OR( AND(TRIM(D37)="P1Y",TRIM(E37)="Annual"), AND(TRIM(D37)="P3Y",TRIM(E37)="Annual"), AND(TRIM(D37)="P3Y",TRIM(E37)="Triennial") ), IF(AND(I37=4%,J37=0%,K37=0%,L37=0%),3%, IF(AND(I37=4%,J37=2.5%,K37=0%,L37=10%),10%, IF(AND(I37=4%,J37=0%,K37=7%,L37=10%),14%,0%))), 0% )))) -> 0.02 | N37: =H37-(H37*M37) -> 12348
A38: CFQ7TTC10RSN | B38: 1 | C38: Microsoft Defender Suite for Microsoft 365 Business Premium | D38: P1Y | E38: Monthly | F38: Commercial | G38: 10458 | H38: 8366.4 | I38: =IF(COUNTIFS(Addendum!C:C,A38,Addendum!D:D,IF(ISNUMBER(B38),TEXT(B38,"0000"),B38),Addendum!E:E,"X")>0,4%,0) -> 0.04 | J38: =IF(COUNTIFS(Addendum!C:C,A38,Addendum!D:D,IF(ISNUMBER(B38),TEXT(B38,"0000"),B38),Addendum!F:F,"X")>0,2.5%,0) -> 0.025 | K38: =IF(COUNTIFS(Addendum!C:C,A38,Addendum!D:D,IF(ISNUMBER(B38),TEXT(B38,"0000"),B38),Addendum!G:G,"X")>0,7%,0) -> 0 | L38: =IF(COUNTIFS(Addendum!C:C,A38,Addendum!D:D,IF(ISNUMBER(B38),TEXT(B38,"0000"),B38),Addendum!I:I,"X")>0,10%,0) -> 0.1 | M38: =IF(AND(I38=0%,J38=0%,K38=0%,L38=0%),0%, IF(OR(TRIM(E38)="OneTime",TRIM(D38)=""),0%, IF( OR( TRIM(D38)="P1M", AND(TRIM(D38)="P1Y",TRIM(E38)="Monthly"), AND(TRIM(D38)="P3Y",TRIM(E38)="Monthly") ), IF(AND(I38=4%,J38=0%,K38=0%,L38=0%),1%, IF(AND(I38=4%,J38=2.5%,K38=0%,L38=10%),2%, IF(AND(I38=4%,J38=0%,K38=7%,L38=10%),3%,0%))), IF( OR( AND(TRIM(D38)="P1Y",TRIM(E38)="Annual"), AND(TRIM(D38)="P3Y",TRIM(E38)="Annual"), AND(TRIM(D38)="P3Y",TRIM(E38)="Triennial") ), IF(AND(I38=4%,J38=0%,K38=0%,L38=0%),3%, IF(AND(I38=4%,J38=2.5%,K38=0%,L38=10%),10%, IF(AND(I38=4%,J38=0%,K38=7%,L38=10%),14%,0%))), 0% )))) -> 0.02 | N38: =H38-(H38*M38) -> 8199.072
A39: CFQ7TTC10RSN | B39: 7 | C39: Microsoft Purview Suite for Microsoft 365 Business Premium (Non-Profit Pricing) | D39: P1Y | E39: Monthly | F39: Charity | G39: 4221 | H39: 3798.96 | I39: =IF(COUNTIFS(Addendum!C:C,A39,Addendum!D:D,IF(ISNUMBER(B39),TEXT(B39,"0000"),B39),Addendum!E:E,"X")>0,4%,0) -> 0.04 | J39: =IF(COUNTIFS(Addendum!C:C,A39,Addendum!D:D,IF(ISNUMBER(B39),TEXT(B39,"0000"),B39),Addendum!F:F,"X")>0,2.5%,0) -> 0.025 | K39: =IF(COUNTIFS(Addendum!C:C,A39,Addendum!D:D,IF(ISNUMBER(B39),TEXT(B39,"0000"),B39),Addendum!G:G,"X")>0,7%,0) -> 0 | L39: =IF(COUNTIFS(Addendum!C:C,A39,Addendum!D:D,IF(ISNUMBER(B39),TEXT(B39,"0000"),B39),Addendum!I:I,"X")>0,10%,0) -> 0.1 | M39: =IF(AND(I39=0%,J39=0%,K39=0%,L39=0%),0%, IF(OR(TRIM(E39)="OneTime",TRIM(D39)=""),0%, IF( OR( TRIM(D39)="P1M", AND(TRIM(D39)="P1Y",TRIM(E39)="Monthly"), AND(TRIM(D39)="P3Y",TRIM(E39)="Monthly") ), IF(AND(I39=4%,J39=0%,K39=0%,L39=0%),1%, IF(AND(I39=4%,J39=2.5%,K39=0%,L39=10%),2%, IF(AND(I39=4%,J39=0%,K39=7%,L39=10%),3%,0%))), IF( OR( AND(TRIM(D39)="P1Y",TRIM(E39)="Annual"), AND(TRIM(D39)="P3Y",TRIM(E39)="Annual"), AND(TRIM(D39)="P3Y",TRIM(E39)="Triennial") ), IF(AND(I39=4%,J39=0%,K39=0%,L39=0%),3%, IF(AND(I39=4%,J39=2.5%,K39=0%,L39=10%),10%, IF(AND(I39=4%,J39=0%,K39=7%,L39=10%),14%,0%))), 0% )))) -> 0.02 | N39: =H39-(H39*M39) -> 3722.9808
... A73: CFQ7TTC0LHRL | B73: 2 | C73: Dataverse Database Capacity add-on | D73: P1Y | E73: Annual | F73: Commercial | G73: 39960 | H73: 29970 | I73: =IF(COUNTIFS(Addendum!C:C,A73,Addendum!D:D,IF(ISNUMBER(B73),TEXT(B73,"0000"),B73),Addendum!E:E,"X")>0,4%,0) -> 0 | J73: =IF(COUNTIFS(Addendum!C:C,A73,Addendum!D:D,IF(ISNUMBER(B73),TEXT(B73,"0000"),B73),Addendum!F:F,"X")>0,2.5%,0) -> 0 | K73: =IF(COUNTIFS(Addendum!C:C,A73,Addendum!D:D,IF(ISNUMBER(B73),TEXT(B73,"0000"),B73),Addendum!G:G,"X")>0,7%,0) -> 0 | L73: =IF(COUNTIFS(Addendum!C:C,A73,Addendum!D:D,IF(ISNUMBER(B73),TEXT(B73,"0000"),B73),Addendum!I:I,"X")>0,10%,0) -> 0 | M73: =IF(AND(I73=0%,J73=0%,K73=0%,L73=0%),0%, IF(OR(TRIM(E73)="OneTime",TRIM(D73)=""),0%, IF( OR( TRIM(D73)="P1M", AND(TRIM(D73)="P1Y",TRIM(E73)="Monthly"), AND(TRIM(D73)="P3Y",TRIM(E73)="Monthly") ), IF(AND(I73=4%,J73=0%,K73=0%,L73=0%),1%, IF(AND(I73=4%,J73=2.5%,K73=0%,L73=10%),2%, IF(AND(I73=4%,J73=0%,K73=7%,L73=10%),3%,0%))), IF( OR( AND(TRIM(D73)="P1Y",TRIM(E73)="Annual"), AND(TRIM(D73)="P3Y",TRIM(E73)="Annual"), AND(TRIM(D73)="P3Y",TRIM(E73)="Triennial") ), IF(AND(I73=4%,J73=0%,K73=0%,L73=0%),3%, IF(AND(I73=4%,J73=2.5%,K73=0%,L73=10%),10%, IF(AND(I73=4%,J73=0%,K73=7%,L73=10%),14%,0%))), 0% )))) -> 0 | N73: =H73-(H73*M73) -> 29970
